Workbook

Sheet INPUT
A1: KONSOL | C1: 46178 | O1: KPI HARI KEMARIN
A2: NO | B2: KOMPONEN KPI | C2: SUB KOMPONEN KPI | D2: BOBOT KPI | E2: TARGET BULANAN | F2: TARGET TAHUNAN | G2: REALISASI | H2: ACH BULANAN | I2: NILAI KPI BULANAN | J2: ACH TAHUNAN | K2: NILAI KPI TAHUNAN | M2: Note: Input hanya pada sel yang tdk berwarna ya gaaeeess!!!!!!!!!!!! | O2: KONSOL | P2: TEGALBOTO | Q2: BASUKI RAHMAD | R2: S PARMAN | S2: KALISAT | T2: MAYANG | U2: SUMBERJATI
A3: 1 | B3: OUTSTANDING LOAN | C3: OSL AKTIF RATA-RATA GADAI | D3: 10 | E3: 101335404812 | F3: 105565098908 | G3: 121174958031 | H3: 118.36 | I3: 11.84 | J3: 114.79 | K3: 11.48 | O3: 11.41 | P3: 11.7 | Q3: 13.49 | R3: 13.97 | S3: 11.45 | T3: 16.18 | U3: 6.1
A4: 2 | B4: OUTSTANDING LOAN | C4: OSL AKTIF RATA-RATA NON GADAI | D4: 5 | E4: 19037305620 | F4: 19243924449 | G4: 18083084925 | H4: 94.73 | I4: 4.74 | J4: 93.97 | K4: 4.7 | O4: 4.7 | P4: 4.69 | S4: 4.23
A5: 3 | B5: OUTSTANDING LOAN | C5: OSL AKTIF RATA-RATA EMAS | D5: 7.5 | E5: 15831048593 | F5: 17752748148 | G5: 19450849057 | H5: 119.45 | I5: 8.96 | J5: 109.57 | K5: 8.22 | O5: 8.16 | P5: 9.82 | Q5: 12.15 | R5: 9.77 | S5: 7.1 | T5: 6 | U5: 5.91
A6: 4 | B6: OUTSTANDING LOAN | C6: OSL GROSS POSISI | D6: 5 | E6: 136702016153 | F6: 147179617614 | G6: 165937167123 | H6: 110 | I6: 5.5 | J6: 110 | K6: 5.5 | O6: 5.5 | P6: 5.5 | Q6: 5.45 | R6: 5.5 | S6: 5.49 | T6: 5.5 | U6: 1.44
A7: 5 | B7: LABA USAHA | C7: LABA USAHA | D7: 10 | E7: 6716119032 | F7: 21028689608 | G7: 9.123839e+09 | H7: 89.52 | I7: 8.95 | J7: 43.39 | K7: 4.34 | O7: 4.34 | P7: 4.36 | Q7: 4.24 | R7: 4.09 | S7: 4.71 | T7: 4.35 | U7: 1.68
A8: 6 | B8: CIR | C8: CIR | G8: 20.06 | H8: 0 | J8: 0
A9: 7 | B9: NASABAH | C9: NASABAH BARU | D9: 5 | E9: 2781.8646 | F9: 8990 | G9: 4345 | H9: 106.66 | I9: 5.33 | J9: 48.33 | K9: 2.42 | O9: 2.07 | P9: 4.84 | Q9: 1.06 | R9: 1.51 | S9: 1.4 | T9: 0.94 | U9: 0.3
A10: 8 | B10: NASABAH | C10: NASABAH BARU AGEN | D10: 2.5 | E10: 133 | F10: 400 | G10: 351 | H10: 110 | I10: 2.75 | J10: 87.75 | K10: 2.19 | O10: 1.85 | P10: 2.75 | Q10: 1.71 | R10: 1.98 | S10: 2.75 | T10: 1.29 | U10: 0.25
A11: 9 | B11: NASABAH | C11: NASABAH PEMBIAYAAN TAHUNAN | D11: 5 | E11: 18493 | F11: 27491 | G11: 18503 | H11: 90.78 | I11: 4.54 | J11: 67.31 | K11: 3.37 | O11: 3.22 | P11: 3.64 | Q11: 2.79 | R11: 3.16 | S11: 3.38 | T11: 3 | U11: 1.01
A12: 10 | B12: NASABAH | C12: NASABAH TABUNGAN EMAS | D12: 5 | E12: 2424 | F12: 2877 | G12: 2710 | H12: 107.11 | I12: 5.36 | J12: 94.2 | K12: 4.71 | O12: 4.68 | P12: 4.7 | Q12: 4.64 | R12: 4.96 | S12: 4.79 | T12: 4.59 | U12: 2.39
A13: 11 | B13: KUALITAS KREDIT | C13: NPL GADAI | D13: 3 | E13: 0.29 | F13: 0.31 | G13: 0.09 | H13: 110 | I13: 3.3 | J13: 110 | K13: 3.3 | O13: 3.3 | P13: 3.3 | Q13: 3.3 | R13: 3.3 | S13: 3.3 | T13: 3.3 | U13: 4.4
A14: 12 | B14: KUALITAS KREDIT | C14: NPL NON GADAI | D14: 2 | E14: 3.18 | F14: 3.06 | G14: 2.26 | H14: 110 | I14: 2.2 | J14: 110 | K14: 2.2 | O14: 1.75 | P14: 1.96 | Q14: 2.2 | R14: 2.2 | S14: 1.11 | T14: 2.2
A15: 13 | B15: KUALITAS KREDIT | C15: NPL EMAS | D15: 2.5 | E15: 0.87 | F15: 0.87 | G15: 0.16 | H15: 110 | I15: 2.75 | J15: 110 | K15: 2.75 | O15: 2.75 | P15: 2.75 | Q15: 2.75 | R15: 2.75 | S15: 2.75 | T15: 2.75 | U15: 3.85
A16: 14 | B16: KUALITAS KREDIT | C16: LAR GADAI | D16: 3 | E16: 5.06 | F16: 2.75 | G16: 6.52 | H16: 81.44 | I16: 2.44 | J16: 85.89 | K16: 2.58 | O16: 2.65 | P16: 2.72 | Q16: 1.76 | R16: 2.89 | S16: 2.84 | T16: 3.3 | U16: 4.4
A17: 15 | B17: KUALITAS KREDIT | C17: LAR NON GADAI | D17: 2 | E17: 14.48 | F17: 14.59 | G17: 12.77 | H17: 110 | I17: 2.2 | J17: 110 | K17: 2.2 | O17: 1.41 | P17: 1.59 | Q17: 2.2 | R17: 2.2 | S17: 1.11 | T17: 0.73
A18: 16 | B18: KUALITAS KREDIT | C18: LAR EMAS | D18: 2.5 | E18: 10.82 | F18: 11.04 | G18: 7.09 | H18: 110 | I18: 2.75 | J18: 110 | K18: 2.75 | O18: 2.75 | P18: 2.75 | Q18: 2.75 | R18: 2.75 | S18: 1.56 | T18: 2.75 | U18: 1.37
A19: 17 | B19: REVAMP PEGADAIAN BRAND | C19: BRAND AWARENESS | H19: 0 | J19: 0
A20: 18 | B20: GOLD ECOSYSTEM | C20: DEPOSITO EMAS | D20: 2.5 | E20: 4848 | F20: 6312 | G20: 3493 | H20: 66.7 | I20: 1.67 | J20: 55.34 | K20: 1.38 | O20: 1.37 | P20: 1.58 | Q20: 1.14 | R20: 1.38 | S20: 0.45 | T20: 1.12 | U20: 0
A21: 19 | B21: GOLD ECOSYSTEM | C21: TABUNGAN EMAS | D21: 2.5 | E21: 23697 | F21: 27153 | G21: 24585.093 | H21: 101.29 | I21: 2.53 | J21: 90.54 | K21: 2.26 | O21: 2.25 | P21: 2.51 | Q21: 2.07 | R21: 1.84 | S21: 1.73 | T21: 1.47 | U21: 0
A22: 20 | B22: GOLD ECOSYSTEM | C22: GRAMASI PRODUK GALERI 24 | D22: 5 | E22: 3267 | F22: 10944 | G22: 5735 | H22: 110 | I22: 5.5 | J22: 52.4 | K22: 2.62 | O22: 2.5 | P22: 4.08 | Q22: 2.58 | R22: 1.18 | S22: 1.95 | T22: 1.48 | U22: 0.1
A23: 21 | B23: PEGADAIAN DIGITAL TRING! | C23: NASABAH TRING! | D23: 5 | E23: 2700 | F23: 8978 | G23: 7020 | H23: 110 | I23: 5.5 | J23: 78.19 | K23: 3.91 | O23: 3.71 | P23: 4.19 | Q23: 3.99 | R23: 3.65 | S23: 4.28 | T23: 2.02 | U23: 0.58
A24: 22 | B24: PEGADAIAN DIGITAL TRING! | C24: OSL LAYANAN TRING! | D24: 5 | E24: 3473816911 | F24: 5988096541 | G24: 4732746985 | H24: 110 | I24: 5.5 | J24: 79.04 | K24: 3.95 | O24: 4.05 | P24: 5.5 | Q24: 4 | R24: 2.7 | S24: 3.36 | T24: 1.6 | U24: 0.97
A25: 23 | B25: PEGADAIAN DIGITAL TRING! | C25: FREKUENSI TRANSAKSI TRING! | D25: 5 | E25: 28486 | F25: 94702 | G25: 33934 | H25: 77.88 | I25: 3.89 | J25: 35.83 | K25: 1.79 | O25: 1.64 | P25: 2.28 | Q25: 1.46 | R25: 1.26 | S25: 1.75 | T25: 0.92 | U25: 0.22
A26: 24 | B26: SINERGI HOLDING UMI | C26: CASHLESS DISBURSEMENT | D26: 2 | E26: 78.76 | F26: 78.76 | G26: 77.94 | H26: 98.96 | I26: 1.98 | J26: 98.96 | K26: 1.98 | O26: 1.98 | P26: 1.83 | Q26: 1.96 | R26: 1.89 | S26: 2.14 | T26: 2.2 | U26: 2.2
A27: 25 | B27: SINERGI HOLDING UMI | C27: OSL SINERGI HOLDING | D27: 1.5 | E27: 351558701 | F27: 830889743 | G27: 1411178440 | H27: 110 | I27: 1.65 | J27: 110 | K27: 1.65 | O27: 1.65 | P27: 1.65 | Q27: 0.18 | R27: 1.65 | S27: 1.65 | T27: 1.65 | U27: 1.22
A28: 26 | B28: SINERGI HOLDING UMI | C28: TE SINERGI HOLDING | D28: 1.5 | E28: 3023 | F28: 3711 | G28: 2044.4244 | H28: 64.43 | I28: 0.97 | J28: 55.09 | K28: 0.83 | O28: 0.81 | P28: 0.83 | Q28: 0.42 | R28: 0.31 | S28: 1.29 | T28: 0.9 | U28: 0.94
A29: 27 | B29: KPI STRETCH GOAL | C29: KPI STRETCH GOAL | E29: 14261051088 | F29: 17670748427 | G29: 16474128527 | H29: 109.36 | I29: 0 | J29: 93.23 | K29: 0 | O29: 0 | P29: 0 | Q29: 0 | R29: 0 | S29: 0 | T29: 0 | U29: 0
D30: =SUM(D3:D29) -> 100 | K30: =SUM(K3:K29) -> 83.08
A31: TEGALBOTO | O31: =SUM(O3:O29) -> 80.5 | P31: =SUM(P3:P29) -> 91.52 | Q31: =SUM(Q3:Q29) -> 78.29 | R31: =SUM(R3:R29) -> 76.89 | S31: =SUM(S3:S29) -> 76.57 | T31: =SUM(T3:T29) -> 70.24 | U31: =SUM(U3:U29) -> 39.33
A32: NO | B32: KOMPONEN KPI | C32: SUB KOMPONEN KPI | D32: BOBOT KPI | E32: TARGET BULANAN | F32: TARGET TAHUNAN | G32: REALISASI | H32: ACH BULANAN | I32: NILAI KPI BULANAN | J32: ACH TAHUNAN | K32: NILAI KPI TAHUNAN
A33: 1 | B33: OUTSTANDING LOAN | C33: OSL AKTIF RATA-RATA GADAI | D33: 10 | E33: 4.0907806e+10 | F33: 42622811780 | G33: 50161302371 | H33: 121.37 | I33: 12.14 | J33: 117.69 | K33: 11.77
A34: 2 | B34: OUTSTANDING LOAN | C34: OSL AKTIF RATA-RATA NON GADAI | D34: 5 | E34: 1.1729351e+10 | F34: 11839554017 | G34: 11142140348 | H34: 94.77 | I34: 4.74 | J34: 94.11 | K34: 4.71
A35: 3 | B35: OUTSTANDING LOAN | C35: OSL AKTIF RATA-RATA EMAS | D35: 7.5 | E35: 7.6980742e+09 | F35: 8633448014 | G35: 11434722100 | H35: 144.41 | I35: 10.83 | J35: 132.45 | K35: 9.93
A36: 4 | B36: OUTSTANDING LOAN | C36: OSL GROSS POSISI | D36: 5 | E36: 6.0920093e+10 | F36: 65834609329 | G36: 76702946469 | H36: 110 | I36: 5.5 | J36: 110 | K36: 5.5
A37: 5 | B37: LABA USAHA | C37: LABA USAHA | D37: 10 | E37: 2.6371481e+09 | F37: 8257115195 | G37: 3.6007065e+09 | H37: 89.98 | I37: 9 | J37: 43.61 | K37: 4.36
A38: 6 | B38: CIR | C38: CIR | G38: 24.91 | H38: 0 | J38: 0
A39: 7 | B39: NASABAH | C39: NASABAH BARU | D39: 5 | E39: 781.5597 | F39: 2255 | G39: 2333 | H39: 110 | I39: 5.5 | J39: 103.44 | K39: 5.17
A40: 8 | B40: NASABAH | C40: NASABAH BARU AGEN | D40: 2.5 | E40: 20.6567 | F40: 62 | G40: 69 | H40: 110 | I40: 2.75 | J40: 110 | K40: 2.75
...

Sheet KONSOL
A1: 14200 - CP TEGALBOTO (konsolidasi)
A2: =INPUT!C1 -> 46178
A3: NO | B3: KOMPONEN KPI | C3: SUB KOMPONEN KPI | D3: CAPPING | E3: BOBOT KPI | F3: TARGET | H3: REALISASI | I3: ACH (%) | J3: KPI TAHUNAN | L3: DELTA HARIAN | N3: KPI INDIVIDU | Q3: SELISIH TARGET
F4: RKAP | G4: EXCEED | J4: KEMARIN | K4: HARI INI | N4: INDEX | O4: KPI | Q4: RKAP | R4: EXCEED
A5: 1 | B5: OUTSTANDING LOAN | C5: OSL AKTIF RATA-RATA GADAI | D5: Unlimited | E5: =INPUT!D3 -> 10 | F5: =INPUT!F3 -> 105565098908 | G5: =F5*110% -> 1.1612161e+11 | H5: =INPUT!G3 -> 121174958031 | I5: =INPUT!J3 -> 114.79 | J5: =INPUT!O3 -> 11.41 | K5: =INPUT!K3 -> 11.48 | L5: =K5-J5 -> 0.07 | Q5: =H5-F5 -> 15609859123 | R5: =H5-G5 -> 5.0533492e+09
C6: OSL AKTIF RATA-RATA NON GADAI | D6: 110 | E6: =INPUT!D4 -> 5 | F6: =INPUT!F4 -> 19243924449 | G6: =F6*110% -> 2.1168317e+10 | H6: =INPUT!G4 -> 18083084925 | I6: =INPUT!J4 -> 93.97 | J6: =INPUT!O4 -> 4.7 | K6: =INPUT!K4 -> 4.7 | L6: =K6-J6 -> 0 | Q6: =H6-F6 -> -1160839524 | R6: =H6-G6 -> -3.085232e+09
C7: OSL AKTIF RATA-RATA EMAS | D7: Unlimited | E7: =INPUT!D5 -> 7.5 | F7: =INPUT!F5 -> 17752748148 | G7: =F7*110% -> 1.9528023e+10 | H7: =INPUT!G5 -> 19450849057 | I7: =INPUT!J5 -> 109.57 | J7: =INPUT!O5 -> 8.16 | K7: =INPUT!K5 -> 8.22 | L7: =K7-J7 -> 0.06 | Q7: =H7-F7 -> 1698100909 | R7: =H7-G7 -> -77173906
C8: OSL GROSS POSISI | D8: 110 | E8: =INPUT!D6 -> 5 | F8: =INPUT!F6 -> 147179617614 | G8: =F8*110% -> 1.6189758e+11 | H8: =INPUT!G6 -> 165937167123 | I8: =INPUT!J6 -> 110 | J8: =INPUT!O6 -> 5.5 | K8: =INPUT!K6 -> 5.5 | L8: =K8-J8 -> 0 | Q8: =H8-F8 -> 18757549509 | R8: =H8-G8 -> 4.0395877e+09
A9: 2 | B9: LABA USAHA | C9: LABA USAHA | D9: 110 | E9: =INPUT!D7 -> 10 | F9: =INPUT!F7 -> 21028689608 | G9: =F9*110% -> 2.3131559e+10 | H9: =INPUT!G7 -> 9.123839e+09 | I9: =INPUT!J7 -> 43.39 | J9: =INPUT!O7 -> 4.34 | K9: =INPUT!K7 -> 4.34 | L9: =K9-J9 -> 0 | Q9: =H9-F9 -> -1.1904851e+10 | R9: =H9-G9 -> -1.400772e+10
A10: 3 | B10: CIR | C10: CIR | D10: 110 | F10: =INPUT!F8 -> 0 | G10: =F10*110% -> 0 | H10: =INPUT!G8 -> 20.06 | I10: =INPUT!J8 -> 0 | J10: =INPUT!O8 -> 0 | K10: =INPUT!K8 -> 0 | L10: =K10-J10 -> 0 | Q10: =H10-F10 -> 20.06 | R10: =H10-G10 -> 20.06
A11: 4 | B11: NASABAH | C11: NASABAH BARU | D11: 110 | E11: =INPUT!D9 -> 5 | F11: =INPUT!F9 -> 8990 | G11: =F11*110% -> 9889 | H11: =INPUT!G9 -> 4345 | I11: =INPUT!J9 -> 48.33 | J11: =INPUT!O9 -> 2.07 | K11: =INPUT!K9 -> 2.42 | L11: =K11-J11 -> 0.35 | Q11: =H11-F11 -> -4645 | R11: =H11-G11 -> -5544
C12: NASABAH BARU AGEN | D12: 110 | E12: =INPUT!D10 -> 2.5 | F12: =INPUT!F10 -> 400 | G12: =F12*110% -> 440 | H12: =INPUT!G10 -> 351 | I12: =INPUT!J10 -> 87.75 | J12: =INPUT!O10 -> 1.85 | K12: =INPUT!K10 -> 2.19 | L12: =K12-J12 -> 0.34 | Q12: =H12-F12 -> -49 | R12: =H12-G12 -> -89
C13: NASABAH PEMBIAYAAN TAHUNAN | D13: 110 | E13: =INPUT!D11 -> 5 | F13: =INPUT!F11 -> 27491 | G13: =F13*110% -> 30240.1 | H13: =INPUT!G11 -> 18503 | I13: =INPUT!J11 -> 67.31 | J13: =INPUT!O11 -> 3.22 | K13: =INPUT!K11 -> 3.37 | L13: =K13-J13 -> 0.15 | Q13: =H13-F13 -> -8988 | R13: =H13-G13 -> -11737.1
C14: NASABAH TABUNGAN EMAS | D14: 110 | E14: =INPUT!D12 -> 5 | F14: =INPUT!F12 -> 2877 | G14: =F14*110% -> 3164.7 | H14: =INPUT!G12 -> 2710 | I14: =INPUT!J12 -> 94.2 | J14: =INPUT!O12 -> 4.68 | K14: =INPUT!K12 -> 4.71 | L14: =K14-J14 -> 0.03 | Q14: =H14-F14 -> -167 | R14: =H14-G14 -> -454.7
A15: 5 | B15: KUALITAS KREDIT | C15: NPL GADAI | D15: 110 | E15: =INPUT!D13 -> 3 | F15: =INPUT!F13 -> 0.31 | G15: =F15-(F15*10%) -> 0.279 | H15: =INPUT!G13 -> 0.09 | I15: =INPUT!J13 -> 110 | J15: =INPUT!O13 -> 3.3 | K15: =INPUT!K13 -> 3.3 | L15: =K15-J15 -> 0 | Q15: =F15-H15 -> 0.22 | R15: =G15-H15 -> 0.189
C16: NPL NON GADAI | D16: 110 | E16: =INPUT!D14 -> 2 | F16: =INPUT!F14 -> 3.06 | G16: =F16-(F16*10%) -> 2.754 | H16: =INPUT!G14 -> 2.26 | I16: =INPUT!J14 -> 110 | J16: =INPUT!O14 -> 1.75 | K16: =INPUT!K14 -> 2.2 | L16: =K16-J16 -> 0.45 | Q16: =F16-H16 -> 0.8 | R16: =G16-H16 -> 0.494
C17: NPL EMAS | D17: 110 | E17: =INPUT!D15 -> 2.5 | F17: =INPUT!F15 -> 0.87 | G17: =F17-(F17*10%) -> 0.783 | H17: =INPUT!G15 -> 0.16 | I17: =INPUT!J15 -> 110 | J17: =INPUT!O15 -> 2.75 | K17: =INPUT!K15 -> 2.75 | L17: =K17-J17 -> 0 | Q17: =F17-H17 -> 0.71 | R17: =G17-H17 -> 0.623
C18: LAR GADAI | D18: 110 | E18: =INPUT!D16 -> 3 | F18: =INPUT!F16 -> 2.75 | G18: =F18-(F18*10%) -> 2.475 | H18: =INPUT!G16 -> 6.52 | I18: =INPUT!J16 -> 85.89 | J18: =INPUT!O16 -> 2.65 | K18: =INPUT!K16 -> 2.58 | L18: =K18-J18 -> -0.07 | Q18: =F18-H18 -> -3.77 | R18: =G18-H18 -> -4.045
C19: LAR NON GADAI | D19: 110 | E19: =INPUT!D17 -> 2 | F19: =INPUT!F17 -> 14.59 | G19: =F19-(F19*10%) -> 13.131 | H19: =INPUT!G17 -> 12.77 | I19: =INPUT!J17 -> 110 | J19: =INPUT!O17 -> 1.41 | K19: =INPUT!K17 -> 2.2 | L19: =K19-J19 -> 0.79 | Q19: =F19-H19 -> 1.82 | R19: =G19-H19 -> 0.361
C20: LAR EMAS | D20: 110 | E20: =INPUT!D18 -> 2.5 | F20: =INPUT!F18 -> 11.04 | G20: =F20-(F20*10%) -> 9.936 | H20: =INPUT!G18 -> 7.09 | I20: =INPUT!J18 -> 110 | J20: =INPUT!O18 -> 2.75 | K20: =INPUT!K18 -> 2.75 | L20: =K20-J20 -> 0 | Q20: =F20-H20 -> 3.95 | R20: =G20-H20 -> 2.846
A21: 6 | B21: REVAMP PEGADAIAN BRAND | C21: BRAND AWARENESS | D21: 110 | F21: =INPUT!F19 -> 0 | H21: =INPUT!G19 -> 0 | I21: =INPUT!J19 -> 0 | J21: =INPUT!O19 -> 0 | K21: =INPUT!K19 -> 0 | L21: =K21-J21 -> 0 | Q21: =H21-F21 -> 0 | R21: =H21-G21 -> 0
A22: 7 | B22: GOLD ECOSYSTEM | C22: DEPOSITO EMAS | D22: Unlimited | E22: =INPUT!D20 -> 2.5 | F22: =INPUT!F20 -> 6312 | G22: =F22*110% -> 6943.2 | H22: =INPUT!G20 -> 3493 | I22: =INPUT!J20 -> 55.34 | J22: =INPUT!O20 -> 1.37 | K22: =INPUT!K20 -> 1.38 | L22: =K22-J22 -> 0.01 | Q22: =H22-F22 -> -2819 | R22: =H22-G22 -> -3450.2
C23: TABUNGAN EMAS | D23: 110 | E23: =INPUT!D21 -> 2.5 | F23: =INPUT!F21 -> 27153 | G23: =F23*110% -> 29868.3 | H23: =INPUT!G21 -> 24585.093 | I23: =INPUT!J21 -> 90.54 | J23: =INPUT!O21 -> 2.25 | K23: =INPUT!K21 -> 2.26 | L23: =K23-J23 -> 0.01 | Q23: =H23-F23 -> -2567.9066 | R23: =H23-G23 -> -5283.2066
C24: GRAMASI PRODUK GALERI 24 | D24: 110 | E24: =INPUT!D22 -> 5 | F24: =INPUT!F22 -> 10944 | G24: =F24*110% -> 12038.4 | H24: =INPUT!G22 -> 5735 | I24: =INPUT!J22 -> 52.4 | J24: =INPUT!O22 -> 2.5 | K24: =INPUT!K22 -> 2.62 | L24: =K24-J24 -> 0.12 | Q24: =H24-F24 -> -5209 | R24: =H24-G24 -> -6303.4
A25: 8 | B25: PEGADAIAN DIGITAL TRING! | C25: NASABAH TRING! | D25: 110 | E25: =INPUT!D23 -> 5 | F25: =INPUT!F23 -> 8978 | G25: =F25*110% -> 9875.8 | H25: =INPUT!G23 -> 7020 | I25: =INPUT!J23 -> 78.19 | J25: =INPUT!O23 -> 3.71 | K25: =INPUT!K23 -> 3.91 | L25: =K25-J25 -> 0.2 | Q25: =H25-F25 -> -1958 | R25: =H25-G25 -> -2855.8
C26: OSL LAYANAN TRING! | D26: 110 | E26: =INPUT!D24 -> 5 | F26: =INPUT!F24 -> 5988096541 | G26: =F26*110% -> 6.5869062e+09 | H26: =INPUT!G24 -> 4732746985 | I26: =INPUT!J24 -> 79.04 | J26: =INPUT!O24 -> 4.05 | K26: =INPUT!K24 -> 3.95 | L26: =K26-J26 -> -0.1 | Q26: =H26-F26 -> -1255349556 | R26: =H26-G26 -> -1.8541592e+09
C27: FREKUENSI TRANSAKSI TRING! | D27: 110 | E27: =INPUT!D25 -> 5 | F27: =INPUT!F25 -> 94702 | G27: =F27*110% -> 104172.2 | H27: =INPUT!G25 -> 33934 | I27: =INPUT!J25 -> 35.83 | J27: =INPUT!O25 -> 1.64 | K27: =INPUT!K25 -> 1.79 | L27: =K27-J27 -> 0.15 | Q27: =H27-F27 -> -60768 | R27: =H27-G27 -> -70238.2
A28: 9 | B28: SINERGI HOLDING UMI | C28: CASHLESS DISBURSEMENT | D28: 110 | E28: =INPUT!D26 -> 2 | F28: =INPUT!F26 -> 78.76 | G28: =F28*110% -> 86.636 | H28: =INPUT!G26 -> 77.94 | I28: =INPUT!J26 -> 98.96 | J28: =INPUT!O26 -> 1.98 | K28: =INPUT!K26 -> 1.98 | L28: =K28-J28 -> 0 | Q28: =H28-F28 -> -0.82 | R28: =H28-G28 -> -8.696
C29: OSL SINERGI HOLDING | D29: 110 | E29: =INPUT!D27 -> 1.5 | F29: =INPUT!F27 -> 830889743 | G29: =F29*110% -> 9.1397872e+08 | H29: =INPUT!G27 -> 1411178440 | I29: =INPUT!J27 -> 110 | J29: =INPUT!O27 -> 1.65 | K29: =INPUT!K27 -> 1.65 | L29: =K29-J29 -> 0 | Q29: =H29-F29 -> 580288697 | R29: =H29-G29 -> 4.9719972e+08
C30: TE SINERGI HOLDING | D30: 110 | E30: =INPUT!D28 -> 1.5 | F30: =INPUT!F28 -> 3711 | G30: =F30*110% -> 4082.1 | H30: =INPUT!G28 -> 2044.4244 | I30: =INPUT!J28 -> 55.09 | J30: =INPUT!O28 -> 0.81 | K30: =INPUT!K28 -> 0.83 | L30: =K30-J30 -> 0.02 | Q30: =H30-F30 -> -1666.5756 | R30: =H30-G30 -> -2037.6756
A31: 10 | B31: KPI STRETCH GOAL | C31: KPI STRETCH GOAL | F31: =INPUT!F29 -> 17670748427 | H31: =INPUT!G29 -> 16474128527 | I31: =INPUT!J29 -> 93.23 | J31: =INPUT!O29 -> 0 | K31: =INPUT!K29 -> 0 | L31: =K31-J31 -> 0
A32: TOTAL | E32: =SUM(E5:E31) -> 100 | J32: =SUM(J5:J31) -> 80.5 | K32: =SUM(K5:K31) -> 83.08 | L32: =SUM(L5:L31) -> 2.58

Sheet TEGALBOTO
A1: 14200 - CP TEGALBOTO (outlet)
A2: =KONSOL!A2 -> 46178
A3: NO | B3: KOMPONEN KPI | C3: SUB KOMPONEN KPI | D3: CAPPING | E3: BOBOT KPI | F3: TARGET | H3: REALISASI | I3: ACH (%) | J3: KPI TAHUNAN | L3: DELTA HARIAN | N3: KPI INDIVIDU | Q3: SELISIH TARGET
F4: RKAP | G4: EXCEED | J4: KEMARIN | K4: HARI INI | N4: INDEX | O4: KPI | Q4: RKAP | R4: EXCEED
A5: 1 | B5: OUTSTANDING LOAN | C5: OSL AKTIF RATA-RATA GADAI | D5: Unlimited | E5: =INPUT!D33 -> 10 | F5: =INPUT!F33 -> 42622811780 | G5: =F5*110% -> 46885092958 | H5: =INPUT!G33 -> 50161302371 | I5: =INPUT!J33 -> 117.69 | J5: =INPUT!P3 -> 11.7 | K5: =INPUT!K33 -> 11.77 | L5: =K5-J5 -> 0.07 | Q5: =H5-F5 -> 7538490591 | R5: =H5-G5 -> 3276209413
C6: OSL AKTIF RATA-RATA NON GADAI | D6: 110 | E6: =INPUT!D34 -> 5 | F6: =INPUT!F34 -> 11839554017 | G6: =F6*110% -> 1.3023509e+10 | H6: =INPUT!G34 -> 11142140348 | I6: =INPUT!J34 -> 94.11 | J6: =INPUT!P4 -> 4.69 | K6: =INPUT!K34 -> 4.71 | L6: =K6-J6 -> 0.02 | Q6: =H6-F6 -> -697413669 | R6: =H6-G6 -> -1.8813691e+09
C7: OSL AKTIF RATA-RATA EMAS | D7: Unlimited | E7: =INPUT!D35 -> 7.5 | F7: =INPUT!F35 -> 8633448014 | G7: =F7*110% -> 9.4967928e+09 | H7: =INPUT!G35 -> 11434722100 | I7: =INPUT!J35 -> 132.45 | J7: =INPUT!P5 -> 9.82 | K7: =INPUT!K35 -> 9.93 | L7: =K7-J7 -> 0.11 | Q7: =H7-F7 -> 2801274086 | R7: =H7-G7 -> 1.9379293e+09
C8: OSL GROSS POSISI | D8: 110 | E8: =INPUT!D36 -> 5 | F8: =INPUT!F36 -> 65834609329 | G8: =F8*110% -> 7.241807e+10 | H8: =INPUT!G36 -> 76702946469 | I8: =INPUT!J36 -> 110 | J8: =INPUT!P6 -> 5.5 | K8: =INPUT!K36 -> 5.5 | L8: =K8-J8 -> 0 | Q8: =H8-F8 -> 10868337140 | R8: =H8-G8 -> 4.2848762e+09
A9: 2 | B9: LABA USAHA | C9: LABA USAHA | D9: 110 | E9: =INPUT!D37 -> 10 | F9: =INPUT!F37 -> 8257115195 | G9: =F9*110% -> 9.0828267e+09 | H9: =INPUT!G37 -> 3.6007065e+09 | I9: =INPUT!J37 -> 43.61 | J9: =INPUT!P7 -> 4.36 | K9: =INPUT!K37 -> 4.36 | L9: =K9-J9 -> 0 | Q9: =H9-F9 -> -4.6564087e+09 | R9: =H9-G9 -> -5.4821202e+09
A10: 3 | B10: CIR | C10: CIR | D10: 110 | F10: =INPUT!F38 -> 0 | G10: =F10*110% -> 0 | I10: =INPUT!J38 -> 0 | J10: =INPUT!P8 -> 0 | K10: =INPUT!K38 -> 0 | L10: =K10-J10 -> 0 | Q10: =H10-F10 -> 0 | R10: =H10-G10 -> 0
A11: 4 | B11: NASABAH | C11: NASABAH BARU | D11: 110 | E11: =INPUT!D39 -> 5 | F11: =INPUT!F39 -> 2255 | G11: =F11*110% -> 2480.5 | H11: =INPUT!G39 -> 2333 | I11: =INPUT!J39 -> 103.44 | J11: =INPUT!P9 -> 4.84 | K11: =INPUT!K39 -> 5.17 | L11: =K11-J11 -> 0.33 | Q11: =H11-F11 -> 78 | R11: =H11-G11 -> -147.5
C12: NASABAH BARU AGEN | D12: 110 | E12: =INPUT!D40 -> 2.5 | F12: =INPUT!F40 -> 62 | G12: =F12*110% -> 68.2 | H12: =INPUT!G40 -> 69 | I12: =INPUT!J40 -> 110 | J12: =INPUT!P10 -> 2.75 | K12: =INPUT!K40 -> 2.75 | L12: =K12-J12 -> 0 | Q12: =H12-F12 -> 7 | R12: =H12-G12 -> 0.8
C13: NASABAH PEMBIAYAAN TAHUNAN | D13: 110 | E13: =INPUT!D41 -> 5 | F13: =INPUT!F41 -> 8494 | G13: =F13*110% -> 9343.4 | H13: =INPUT!G41 -> 6389 | I13: =INPUT!J41 -> 75.22 | J13: =INPUT!P11 -> 3.64 | K13: =INPUT!K41 -> 3.76 | L13: =K13-J13 -> 0.12 | Q13: =H13-F13 -> -2105 | R13: =H13-G13 -> -2954.4
C14: NASABAH TABUNGAN EMAS | D14: 110 | E14: =INPUT!D42 -> 5 | F14: =INPUT!F42 -> 1861 | G14: =F14*110% -> 2047.1 | H14: =INPUT!G42 -> 1763 | I14: =INPUT!J42 -> 94.72 | J14: =INPUT!P12 -> 4.7 | K14: =INPUT!K42 -> 4.74 | L14: =K14-J14 -> 0.04 | Q14: =H14-F14 -> -98 | R14: =H14-G14 -> -284.1
A15: 5 | B15: KUALITAS KREDIT | C15: NPL GADAI | D15: 110 | E15: =INPUT!D43 -> 3 | F15: =INPUT!F43 -> 0.31 | G15: =F15-(F15*10%) -> 0.279 | H15: =INPUT!G43 -> 0.16 | I15: =INPUT!J43 -> 110 | J15: =INPUT!P13 -> 3.3 | K15: =INPUT!K43 -> 3.3 | L15: =K15-J15 -> 0 | Q15: =F15-H15 -> 0.15 | R15: =G15-H15 -> 0.119
C16: NPL NON GADAI | D16: 110 | E16: =INPUT!D44 -> 2 | F16: =INPUT!F44 -> 1.95 | G16: =F16-(F16*10%) -> 1.755 | H16: =INPUT!G44 -> 2.15 | I16: =INPUT!J44 -> 90.77 | J16: =INPUT!P14 -> 1.96 | K16: =INPUT!K44 -> 1.82 | L16: =K16-J16 -> -0.14 | Q16: =F16-H16 -> -0.2 | R16: =G16-H16 -> -0.395
C17: NPL EMAS | D17: 110 | E17: =INPUT!D45 -> 2.5 | F17: =INPUT!F45 -> 0.87 | G17: =F17-(F17*10%) -> 0.783 | H17: =INPUT!G45 -> 0 | I17: =INPUT!J45 -> 110 | J17: =INPUT!P15 -> 2.75 | K17: =INPUT!K45 -> 2.75 | L17: =K17-J17 -> 0 | Q17: =F17-H17 -> 0.87 | R17: =G17-H17 -> 0.783
C18: LAR GADAI | D18: 110 | E18: =INPUT!D46 -> 3 | F18: =INPUT!F46 -> 2.75 | G18: =F18-(F18*10%) -> 2.475 | H18: =INPUT!G46 -> 7.51 | I18: =INPUT!J46 -> 36.67 | J18: =INPUT!P16 -> 2.72 | K18: =INPUT!K46 -> 1.1 | L18: =K18-J18 -> -1.62 | Q18: =F18-H18 -> -4.76 | R18: =G18-H18 -> -5.035
C19: LAR NON GADAI | D19: 110 | E19: =INPUT!D47 -> 2 | F19: =INPUT!F47 -> 12.21 | G19: =F19-(F19*10%) -> 10.989 | H19: =INPUT!G47 -> 9.35 | I19: =INPUT!J47 -> 110 | J19: =INPUT!P17 -> 1.59 | K19: =INPUT!K47 -> 2.2 | L19: =K19-J19 -> 0.61 | Q19: =F19-H19 -> 2.86 | R19: =G19-H19 -> 1.639
C20: LAR EMAS | D20: 110 | E20: =INPUT!D48 -> 2.5 | F20: =INPUT!F48 -> 11.04 | G20: =F20-(F20*10%) -> 9.936 | H20: =INPUT!G48 -> 5.22 | I20: =INPUT!J48 -> 110 | J20: =INPUT!P18 -> 2.75 | K20: =INPUT!K48 -> 2.75 | L20: =K20-J20 -> 0 | Q20: =F20-H20 -> 5.82 | R20: =G20-H20 -> 4.716
A21: 6 | B21: REVAMP PEGADAIAN BRAND | C21: BRAND AWARENESS | D21: 110 | F21: =INPUT!F49 -> 0 | H21: =INPUT!G49 -> 0 | I21: =INPUT!J49 -> 0 | J21: =INPUT!P19 -> 0 | K21: =INPUT!K49 -> 0 | L21: =K21-J21 -> 0 | Q21: =H21-F21 -> 0 | R21: =H21-G21 -> 0
A22: 7 | B22: GOLD ECOSYSTEM | C22: DEPOSITO EMAS | D22: Unlimited | E22: =INPUT!D50 -> 2.5 | F22: =INPUT!F50 -> 4328 | G22: =F22*110% -> 4760.8 | H22: =INPUT!G50 -> 2777 | I22: =INPUT!J50 -> 64.17 | J22: =INPUT!P20 -> 1.58 | K22: =INPUT!K50 -> 1.6 | L22: =K22-J22 -> 0.02 | Q22: =H22-F22 -> -1551 | R22: =H22-G22 -> -1983.8
C23: TABUNGAN EMAS | D23: 110 | E23: =INPUT!D51 -> 2.5 | F23: =INPUT!F51 -> 18322 | G23: =F23*110% -> 20154.2 | H23: =INPUT!G51 -> 18501.868 | I23: =INPUT!J51 -> 100.98 | J23: =INPUT!P21 -> 2.51 | K23: =INPUT!K51 -> 2.52 | L23: =K23-J23 -> 0.01 | Q23: =H23-F23 -> 179.8683 | R23: =H23-G23 -> -1652.3317
C24: GRAMASI PRODUK GALERI 24 | D24: 110 | E24: =INPUT!D52 -> 5 | F24: =INPUT!F52 -> 4232 | G24: =F24*110% -> 4655.2 | H24: =INPUT!G52 -> 3492 | I24: =INPUT!J52 -> 82.52 | J24: =INPUT!P22 -> 4.08 | K24: =INPUT!K52 -> 4.13 | L24: =K24-J24 -> 0.05 | Q24: =H24-F24 -> -740 | R24: =H24-G24 -> -1163.2
A25: 8 | B25: PEGADAIAN DIGITAL TRING! | C25: NASABAH TRING! | D25: 110 | E25: =INPUT!D53 -> 5 | F25: =INPUT!F53 -> 4406 | G25: =F25*110% -> 4846.6 | H25: =INPUT!G53 -> 3853 | I25: =INPUT!J53 -> 87.46 | J25: =INPUT!P23 -> 4.19 | K25: =INPUT!K53 -> 4.37 | L25: =K25-J25 -> 0.18 | Q25: =H25-F25 -> -553 | R25: =H25-G25 -> -993.6
C26: OSL LAYANAN TRING! | D26: 110 | E26: =INPUT!D54 -> 5 | F26: =INPUT!F54 -> 2104011861 | G26: =F26*110% -> 2.314413e+09 | H26: =INPUT!G54 -> 2791211509 | I26: =INPUT!J54 -> 110 | J26: =INPUT!P24 -> 5.5 | K26: =INPUT!K54 -> 5.5 | L26: =K26-J26 -> 0 | Q26: =H26-F26 -> 687199648 | R26: =H26-G26 -> 4.7679846e+08
C27: FREKUENSI TRANSAKSI TRING! | D27: 110 | E27: =INPUT!D55 -> 5 | F27: =INPUT!F55 -> 38112 | G27: =F27*110% -> 41923.2 | H27: =INPUT!G55 -> 18890 | I27: =INPUT!J55 -> 49.56 | J27: =INPUT!P25 -> 2.28 | K27: =INPUT!K55 -> 2.48 | L27: =K27-J27 -> 0.2 | Q27: =H27-F27 -> -19222 | R27: =H27-G27 -> -23033.2
A28: 9 | B28: SINERGI HOLDING UMI | C28: CASHLESS DISBURSEMENT | D28: 110 | E28: =INPUT!D56 -> 2 | F28: =INPUT!F56 -> 78.76 | G28: =F28*110% -> 86.636 | H28: =INPUT!G56 -> 72.14 | I28: =INPUT!J56 -> 91.59 | J28: =INPUT!P26 -> 1.83 | K28: =INPUT!K56 -> 1.83 | L28: =K28-J28 -> 0 | Q28: =H28-F28 -> -6.62 | R28: =H28-G28 -> -14.496
C29: OSL SINERGI HOLDING | D29: 110 | E29: =INPUT!D57 -> 1.5 | F29: =INPUT!F57 -> 89612005 | G29: =F29*110% -> 98573206 | H29: =INPUT!G57 -> 271316908 | I29: =INPUT!J57 -> 110 | J29: =INPUT!P27 -> 1.65 | K29: =INPUT!K57 -> 1.65 | L29: =K29-J29 -> 0 | Q29: =H29-F29 -> 181704903 | R29: =H29-G29 -> 1.727437e+08
C30: TE SINERGI HOLDING | D30: 110 | E30: =INPUT!D58 -> 1.5 | F30: =INPUT!F58 -> 2497 | G30: =F30*110% -> 2746.7 | H30: =INPUT!G58 -> 1408.5543 | I30: =INPUT!J58 -> 56.42 | J30: =INPUT!P28 -> 0.83 | K30: =INPUT!K58 -> 0.85 | L30: =K30-J30 -> 0.02 | Q30: =H30-F30 -> -1088.4457 | R30: =H30-G30 -> -1338.1457
A31: 10 | B31: KPI STRETCH GOAL | C31: KPI STRETCH GOAL | F31: =INPUT!F59 -> 8547261445 | H31: =INPUT!G59 -> 10620989386 | I31: =INPUT!J59 -> 124.26 | J31: =INPUT!P29 -> 0 | K31: =INPUT!K59 -> 0 | L31: =K31-J31 -> 0
A32: TOTAL | E32: =SUM(E5:E31) -> 100 | J32: =SUM(J5:J31) -> 91.52 | K32: =SUM(K5:K31) -> 91.54 | L32: =SUM(L5:L31) -> 0.02

Sheet BASUKI RAHMAD
A1: 14201 - UPC BASUKI RAHMAD
A2: =KONSOL!A2 -> 46178
A3: NO | B3: KOMPONEN KPI | C3: SUB KOMPONEN KPI | D3: CAPPING | E3: BOBOT KPI | F3: TARGET | H3: REALISASI | I3: ACH (%) | J3: KPI TAHUNAN | L3: DELTA HARIAN | N3: KPI INDIVIDU | Q3: SELISIH TARGET
F4: RKAP | G4: EXCEED | J4: KEMARIN | K4: HARI INI | N4: INDEX | O4: KPI | Q4: RKAP | R4: EXCEED
A5: 1 | B5: OUTSTANDING LOAN | C5: OSL AKTIF RATA-RATA GADAI | D5: Unlimited | E5: =INPUT!D64 -> 12.5 | F5: =INPUT!F64 -> 15466510610 | G5: =F5*110% -> 1.7013162e+10 | H5: =INPUT!G64 -> 16764118032 | I5: =INPUT!J64 -> 108.39 | J5: =INPUT!Q3 -> 13.49 | K5: =INPUT!K64 -> 13.55 | L5: =K5-J5 -> 0.06 | Q5: =H5-F5 -> 1297607422 | R5: =H5-G5 -> -2.4904364e+08
C6: OSL AKTIF RATA-RATA NON GADAI | D6: 110 | F6: =INPUT!F65 -> 302765834 | G6: =F6*110% -> 3.3304242e+08 | H6: =INPUT!G65 -> 453109283 | I6: =INPUT!J65 -> 0 | J6: =INPUT!Q4 -> 0 | K6: =INPUT!K65 -> 0 | L6: =K6-J6 -> 0 | Q6: =H6-F6 -> 150343449 | R6: =H6-G6 -> 1.2006687e+08
C7: OSL AKTIF RATA-RATA EMAS | D7: Unlimited | E7: =INPUT!D66 -> 10 | F7: =INPUT!F66 -> 1821557621 | G7: =F7*110% -> 2.0037134e+09 | H7: =INPUT!G66 -> 2202367297 | I7: =INPUT!J66 -> 120.91 | J7: =INPUT!Q5 -> 12.15 | K7: =INPUT!K66 -> 12.09 | L7: =K7-J7 -> -0.06 | Q7: =H7-F7 -> 380809676 | R7: =H7-G7 -> 1.9865391e+08
C8: OSL GROSS POSISI | D8: 110 | E8: =INPUT!D67 -> 5 | F8: =INPUT!F67 -> 18190765285 | G8: =F8*110% -> 2.0009842e+10 | H8: =INPUT!G67 -> 20029658285 | I8: =INPUT!J67 -> 110 | J8: =INPUT!Q6 -> 5.45 | K8: =INPUT!K67 -> 5.5 | L8: =K8-J8 -> 0.05 | Q8: =H8-F8 -> 1838893000 | R8: =H8-G8 -> 19816472
A9: 2 | B9: LABA USAHA | C9: LABA USAHA | D9: 110 | E9: =INPUT!D68 -> 10 | F9: =INPUT!F68 -> 3091999153 | G9: =F9*110% -> 3.4011991e+09 | H9: =INPUT!G68 -> 1.3116577e+09 | I9: =INPUT!J68 -> 42.42 | J9: =INPUT!Q7 -> 4.24 | K9: =INPUT!K68 -> 4.24 | L9: =K9-J9 -> 0 | Q9: =H9-F9 -> -1.7803415e+09 | R9: =H9-G9 -> -2.0895414e+09
A10: 3 | B10: CIR | C10: CIR | D10: 110 | F10: =INPUT!F69 -> 0 | G10: =F10*110% -> 0 | I10: =INPUT!J69 -> 0 | J10: =INPUT!Q8 -> 0 | K10: =INPUT!K69 -> 0 | L10: =K10-J10 -> 0 | Q10: =H10-F10 -> 0 | R10: =H10-G10 -> 0
A11: 4 | B11: NASABAH | C11: NASABAH BARU | D11: 110 | E11: =INPUT!D70 -> 5 | F11: =INPUT!F70 -> 1493 | G11: =F11*110% -> 1642.3 | H11: =INPUT!G70 -> 387 | I11: =INPUT!J70 -> 25.92 | J11: =INPUT!Q9 -> 1.06 | K11: =INPUT!K70 -> 1.3 | L11: =K11-J11 -> 0.24 | Q11: =H11-F11 -> -1106 | R11: =H11-G11 -> -1255.3
C12: NASABAH BARU AGEN | D12: 110 | E12: =INPUT!D71 -> 2.5 | F12: =INPUT!F71 -> 85 | G12: =F12*110% -> 93.5 | H12: =INPUT!G71 -> 94 | I12: =INPUT!J71 -> 110 | J12: =INPUT!Q10 -> 1.71 | K12: =INPUT!K71 -> 2.75 | L12: =K12-J12 -> 1.04 | Q12: =H12-F12 -> 9 | R12: =H12-G12 -> 0.5
C13: NASABAH PEMBIAYAAN TAHUNAN | D13: 110 | E13: =INPUT!D72 -> 5 | F13: =INPUT!F72 -> 4586 | G13: =F13*110% -> 5044.6 | H13: =INPUT!G72 -> 2704 | I13: =INPUT!J72 -> 58.96 | J13: =INPUT!Q11 -> 2.79 | K13: =INPUT!K72 -> 2.95 | L13: =K13-J13 -> 0.16 | Q13: =H13-F13 -> -1882 | R13: =H13-G13 -> -2340.6
C14: NASABAH TABUNGAN EMAS | D14: 110 | E14: =INPUT!D73 -> 5 | F14: =INPUT!F73 -> 296 | G14: =F14*110% -> 325.6 | H14: =INPUT!G73 -> 284 | I14: =INPUT!J73 -> 95.92 | J14: =INPUT!Q12 -> 4.64 | K14: =INPUT!K73 -> 4.8 | L14: =K14-J14 -> 0.16 | Q14: =H14-F14 -> -12 | R14: =H14-G14 -> -41.6
A15: 5 | B15: KUALITAS KREDIT | C15: NPL GADAI | D15: 110 | E15: =INPUT!D74 -> 3 | F15: =INPUT!F74 -> 0.31 | G15: =F15-(F15*10%) -> 0.279 | H15: =INPUT!G74 -> 0.08 | I15: =INPUT!J74 -> 110 | J15: =INPUT!Q13 -> 3.3 | K15: =INPUT!K74 -> 3.3 | L15: =K15-J15 -> 0 | Q15: =F15-H15 -> 0.23 | R15: =G15-H15 -> 0.199
C16: NPL NON GADAI | D16: 110 | E16: =INPUT!D75 -> 2 | F16: =INPUT!F75 -> 11.23 | G16: =F16-(F16*10%) -> 10.107 | H16: =INPUT!G75 -> 3.35 | I16: =INPUT!J75 -> 110 | J16: =INPUT!Q14 -> 2.2 | K16: =INPUT!K75 -> 2.2 | L16: =K16-J16 -> 0 | Q16: =F16-H16 -> 7.88 | R16: =G16-H16 -> 6.757
C17: NPL EMAS | D17: 110 | E17: =INPUT!D76 -> 2.5 | F17: =INPUT!F76 -> 0.87 | G17: =F17-(F17*10%) -> 0.783 | H17: =INPUT!G76 -> 0.2 | I17: =INPUT!J76 -> 110 | J17: =INPUT!Q15 -> 2.75 | K17: =INPUT!K76 -> 2.75 | L17: =K17-J17 -> 0 | Q17: =F17-H17 -> 0.67 | R17: =G17-H17 -> 0.583
C18: LAR GADAI | D18: 110 | E18: =INPUT!D77 -> 3 | F18: =INPUT!F77 -> 2.75 | G18: =F18-(F18*10%) -> 2.475 | H18: =INPUT!G77 -> 9.41 | I18: =INPUT!J77 -> 29.27 | J18: =INPUT!Q16 -> 1.76 | K18: =INPUT!K77 -> 0.88 | L18: =K18-J18 -> -0.88 | Q18: =F18-H18 -> -6.66 | R18: =G18-H18 -> -6.935
C19: LAR NON GADAI | D19: 110 | E19: =INPUT!D78 -> 2 | F19: =INPUT!F78 -> 30.9 | G19: =F19-(F19*10%) -> 27.81 | H19: =INPUT!G78 -> 10.39 | I19: =INPUT!J78 -> 110 | J19: =INPUT!Q17 -> 2.2 | K19: =INPUT!K78 -> 2.2 | L19: =K19-J19 -> 0 | Q19: =F19-H19 -> 20.51 | R19: =G19-H19 -> 17.42
C20: LAR EMAS | D20: 110 | E20: =INPUT!D79 -> 2.5 | F20: =INPUT!F79 -> 11.04 | G20: =F20-(F20*10%) -> 9.936 | H20: =INPUT!G79 -> 3.62 | I20: =INPUT!J79 -> 110 | J20: =INPUT!Q18 -> 2.75 | K20: =INPUT!K79 -> 2.75 | L20: =K20-J20 -> 0 | Q20: =F20-H20 -> 7.42 | R20: =G20-H20 -> 6.316
A21: 6 | B21: REVAMP PEGADAIAN BRAND | C21: BRAND AWARENESS | D21: 110 | F21: =INPUT!F80 -> 0 | H21: =INPUT!G80 -> 0 | I21: =INPUT!J80 -> 0 | J21: =INPUT!Q19 -> 0 | K21: =INPUT!K80 -> 0 | L21: =K21-J21 -> 0 | Q21: =H21-F21 -> 0 | R21: =H21-G21 -> 0
A22: 7 | B22: GOLD ECOSYSTEM | C22: DEPOSITO EMAS | D22: Unlimited | E22: =INPUT!D81 -> 2.5 | F22: =INPUT!F81 -> 519 | G22: =F22*110% -> 570.9 | H22: =INPUT!G81 -> 243 | I22: =INPUT!J81 -> 46.84 | J22: =INPUT!Q20 -> 1.14 | K22: =INPUT!K81 -> 1.17 | L22: =K22-J22 -> 0.03 | Q22: =H22-F22 -> -276 | R22: =H22-G22 -> -327.9
C23: TABUNGAN EMAS | D23: 110 | E23: =INPUT!D82 -> 2.5 | F23: =INPUT!F82 -> 2207 | G23: =F23*110% -> 2427.7 | H23: =INPUT!G82 -> 1826.5225 | I23: =INPUT!J82 -> 82.76 | J23: =INPUT!Q21 -> 2.07 | K23: =INPUT!K82 -> 2.07 | L23: =K23-J23 -> 0 | Q23: =H23-F23 -> -380.4775 | R23: =H23-G23 -> -601.1775
C24: GRAMASI PRODUK GALERI 24 | D24: 110 | E24: =INPUT!D83 -> 5 | F24: =INPUT!F83 -> 1379 | G24: =F24*110% -> 1516.9 | H24: =INPUT!G83 -> 733.5 | I24: =INPUT!J83 -> 53.18 | J24: =INPUT!Q22 -> 2.58 | K24: =INPUT!K83 -> 2.66 | L24: =K24-J24 -> 0.08 | Q24: =H24-F24 -> -645.5 | R24: =H24-G24 -> -783.4
A25: 8 | B25: PEGADAIAN DIGITAL TRING! | C25: NASABAH TRING! | D25: 110 | E25: =INPUT!D84 -> 5 | F25: =INPUT!F84 -> 1038 | G25: =F25*110% -> 1141.8 | H25: =INPUT!G84 -> 865 | I25: =INPUT!J84 -> 83.37 | J25: =INPUT!Q23 -> 3.99 | K25: =INPUT!K84 -> 4.17 | L25: =K25-J25 -> 0.18 | Q25: =H25-F25 -> -173 | R25: =H25-G25 -> -276.8
C26: OSL LAYANAN TRING! | D26: 110 | E26: =INPUT!D85 -> 5 | F26: =INPUT!F85 -> 789003568 | G26: =F26*110% -> 8.6790392e+08 | H26: =INPUT!G85 -> 592281535 | I26: =INPUT!J85 -> 75.07 | J26: =INPUT!Q24 -> 4 | K26: =INPUT!K85 -> 3.75 | L26: =K26-J26 -> -0.25 | Q26: =H26-F26 -> -196722033 | R26: =H26-G26 -> -2.7562239e+08
C27: FREKUENSI TRANSAKSI TRING! | D27: 110 | E27: =INPUT!D86 -> 5 | F27: =INPUT!F86 -> 14981 | G27: =F27*110% -> 16479.1 | H27: =INPUT!G86 -> 4790 | I27: =INPUT!J86 -> 31.97 | J27: =INPUT!Q25 -> 1.46 | K27: =INPUT!K86 -> 1.6 | L27: =K27-J27 -> 0.14 | Q27: =H27-F27 -> -10191 | R27: =H27-G27 -> -11689.1
A28: 9 | B28: SINERGI HOLDING UMI | C28: CASHLESS DISBURSEMENT | D28: 110 | E28: =INPUT!D87 -> 2 | F28: =INPUT!F87 -> 78.76 | G28: =F28*110% -> 86.636 | H28: =INPUT!G87 -> 78 | I28: =INPUT!J87 -> 99.04 | J28: =INPUT!Q26 -> 1.96 | K28: =INPUT!K87 -> 1.98 | L28: =K28-J28 -> 0.02 | Q28: =H28-F28 -> -0.76 | R28: =H28-G28 -> -8.636
C29: OSL SINERGI HOLDING | D29: 110 | E29: =INPUT!D88 -> 1.5 | F29: =INPUT!F88 -> 89612005 | G29: =F29*110% -> 98573206 | H29: =INPUT!G88 -> 10389442 | I29: =INPUT!J88 -> 11.59 | J29: =INPUT!Q27 -> 0.18 | K29: =INPUT!K88 -> 0.17 | L29: =K29-J29 -> -0.01 | Q29: =H29-F29 -> -79222563 | R29: =H29-G29 -> -88183764
C30: TE SINERGI HOLDING | D30: 110 | E30: =INPUT!D89 -> 1.5 | F30: =INPUT!F89 -> 261 | G30: =F30*110% -> 287.1 | H30: =INPUT!G89 -> 72.7136 | I30: =INPUT!J89 -> 27.89 | J30: =INPUT!Q28 -> 0.42 | K30: =INPUT!K89 -> 0.42 | L30: =K30-J30 -> 0 | Q30: =H30-F30 -> -188.2864 | R30: =H30-G30 -> -214.3864
A31: 10 | B31: KPI STRETCH GOAL | C31: KPI STRETCH GOAL | F31: =INPUT!F90 -> 1686407864 | H31: =INPUT!G90 -> 1316611637 | I31: =INPUT!J90 -> 78.07 | J31: =INPUT!Q29 -> 0 | K31: =INPUT!K90 -> 0 | L31: =K31-J31 -> 0
A32: TOTAL | E32: =SUM(E5:E31) -> 100 | J32: =SUM(J5:J31) -> 78.29 | K32: =SUM(K5:K31) -> 79.25 | L32: =SUM(L5:L31) -> 0.96

Sheet S PARMAN
A1: 14202 - UPC S PARMAN
A2: =KONSOL!A2 -> 46178
A3: NO | B3: KOMPONEN KPI | C3: SUB KOMPONEN KPI | D3: CAPPING | E3: BOBOT KPI | F3: TARGET | H3: REALISASI | I3: ACH (%) | J3: KPI TAHUNAN | L3: DELTA HARIAN | N3: KPI INDIVIDU | Q3: SELISIH TARGET
F4: RKAP | G4: EXCEED | J4: KEMARIN | K4: HARI INI | N4: INDEX | O4: KPI | Q4: RKAP | R4: EXCEED
A5: 1 | B5: OUTSTANDING LOAN | C5: OSL AKTIF RATA-RATA GADAI | D5: Unlimited | E5: =INPUT!D94 -> 12.5 | F5: =INPUT!F94 -> 12177450584 | G5: =F5*110% -> 1.3395196e+10 | H5: =INPUT!G94 -> 13725362812 | I5: =INPUT!J94 -> 112.71 | J5: =INPUT!R3 -> 13.97 | K5: =INPUT!K94 -> 14.09 | L5: =K5-J5 -> 0.12 | Q5: =H5-F5 -> 1547912228 | R5: =H5-G5 -> 3.3016717e+08
C6: OSL AKTIF RATA-RATA NON GADAI | D6: 110 | F6: =INPUT!F95 -> 413851412 | G6: =F6*110% -> 4.5523655e+08 | H6: =INPUT!G95 -> 632354151 | I6: =INPUT!J95 -> 0 | J6: 0 | K6: =INPUT!K95 -> 0 | L6: =K6-J6 -> 0 | Q6: =H6-F6 -> 218502739 | R6: =H6-G6 -> 1.771176e+08
C7: OSL AKTIF RATA-RATA EMAS | D7: Unlimited | E7: =INPUT!D96 -> 10 | F7: =INPUT!F96 -> 1692515292 | G7: =F7*110% -> 1.8617668e+09 | H7: =INPUT!G96 -> 1687699008 | I7: =INPUT!J96 -> 99.72 | J7: =INPUT!R5 -> 9.77 | K7: =INPUT!K96 -> 9.97 | L7: =K7-J7 -> 0.2 | Q7: =H7-F7 -> -4816284 | R7: =H7-G7 -> -1.7406781e+08
C8: OSL GROSS POSISI | D8: 110 | E8: =INPUT!D97 -> 5 | F8: =INPUT!F97 -> 14629108298 | G8: =F8*110% -> 1.6092019e+10 | H8: =INPUT!G97 -> 17313521531 | I8: =INPUT!J97 -> 110 | J8: =INPUT!R6 -> 5.5 | K8: =INPUT!K97 -> 5.5 | L8: =K8-J8 -> 0 | Q8: =H8-F8 -> 2684413233 | R8: =H8-G8 -> 1.2215024e+09
A9: 2 | B9: LABA USAHA | C9: LABA USAHA | D9: 110 | E9: =INPUT!D98 -> 10 | F9: =INPUT!F98 -> 2440995247 | G9: =F9*110% -> 2.6850948e+09 | H9: =INPUT!G98 -> 9.978779e+08 | I9: =INPUT!J98 -> 40.88 | J9: =INPUT!R7 -> 4.09 | K9: =INPUT!K98 -> 4.09 | L9: =K9-J9 -> 0 | Q9: =H9-F9 -> -1.4431173e+09 | R9: =H9-G9 -> -1.6872169e+09
A10: 3 | B10: CIR | C10: CIR | D10: 110 | F10: =INPUT!F99 -> 0 | G10: =F10*110% -> 0 | I10: =INPUT!J99 -> 0 | J10: =INPUT!R8 -> 0 | K10: =INPUT!K99 -> 0 | L10: =K10-J10 -> 0 | Q10: =H10-F10 -> 0 | R10: =H10-G10 -> 0
A11: 4 | B11: NASABAH | C11: NASABAH BARU | D11: 110 | E11: =INPUT!D100 -> 5 | F11: =INPUT!F100 -> 1416 | G11: =F11*110% -> 1557.6 | H11: =INPUT!G100 -> 588 | I11: =INPUT!J100 -> 41.53 | J11: =INPUT!R9 -> 1.51 | K11: =INPUT!K100 -> 2.08 | L11: =K11-J11 -> 0.57 | Q11: =H11-F11 -> -828 | R11: =H11-G11 -> -969.6
C12: NASABAH BARU AGEN | D12: 110 | E12: =INPUT!D101 -> 2.5 | F12: =INPUT!F101 -> 75 | G12: =F12*110% -> 82.5 | H12: =INPUT!G101 -> 76 | I12: =INPUT!J101 -> 101.96 | J12: =INPUT!R10 -> 1.98 | K12: =INPUT!K101 -> 2.55 | L12: =K12-J12 -> 0.57 | Q12: =H12-F12 -> 1 | R12: =H12-G12 -> -6.5
C13: NASABAH PEMBIAYAAN TAHUNAN | D13: 110 | E13: =INPUT!D102 -> 5 | F13: =INPUT!F102 -> 4133 | G13: =F13*110% -> 4546.3 | H13: =INPUT!G102 -> 2806 | I13: =INPUT!J102 -> 67.88 | J13: =INPUT!R11 -> 3.16 | K13: =INPUT!K102 -> 3.39 | L13: =K13-J13 -> 0.23 | Q13: =H13-F13 -> -1327 | R13: =H13-G13 -> -1740.3
C14: NASABAH TABUNGAN EMAS | D14: 110 | E14: =INPUT!D103 -> 5 | F14: =INPUT!F103 -> 252 | G14: =F14*110% -> 277.2 | H14: =INPUT!G103 -> 246 | I14: =INPUT!J103 -> 97.71 | J14: =INPUT!R12 -> 4.96 | K14: =INPUT!K103 -> 4.89 | L14: =K14-J14 -> -0.07 | Q14: =H14-F14 -> -6 | R14: =H14-G14 -> -31.2
A15: 5 | B15: KUALITAS KREDIT | C15: NPL GADAI | D15: 110 | E15: =INPUT!D104 -> 3 | F15: =INPUT!F104 -> 0.31 | G15: =F15-(F15*10%) -> 0.279 | H15: =INPUT!G104 -> 0.14 | I15: =INPUT!J104 -> 110 | J15: =INPUT!R13 -> 3.3 | K15: =INPUT!K104 -> 3.3 | L15: =K15-J15 -> 0 | Q15: =F15-H15 -> 0.17 | R15: =G15-H15 -> 0.139
C16: NPL NON GADAI | D16: 110 | E16: =INPUT!D105 -> 2 | F16: =INPUT!F105 -> 10.61 | G16: =F16-(F16*10%) -> 9.549 | H16: =INPUT!G105 -> 3.29 | I16: =INPUT!J105 -> 110 | J16: =INPUT!R14 -> 2.2 | K16: =INPUT!K105 -> 2.2 | L16: =K16-J16 -> 0 | Q16: =F16-H16 -> 7.32 | R16: =G16-H16 -> 6.259
C17: NPL EMAS | D17: 110 | E17: =INPUT!D106 -> 2.5 | F17: =INPUT!F106 -> 0.87 | G17: =F17-(F17*10%) -> 0.783 | H17: =INPUT!G106 -> 0.67 | I17: =INPUT!J106 -> 110 | J17: =INPUT!R15 -> 2.75 | K17: =INPUT!K106 -> 2.75 | L17: =K17-J17 -> 0 | Q17: =F17-H17 -> 0.2 | R17: =G17-H17 -> 0.113
C18: LAR GADAI | D18: 110 | E18: =INPUT!D107 -> 3 | F18: =INPUT!F107 -> 2.75 | G18: =F18-(F18*10%) -> 2.475 | H18: =INPUT!G107 -> 6.82 | I18: =INPUT!J107 -> 40.38 | J18: =INPUT!R16 -> 2.89 | K18: =INPUT!K107 -> 1.21 | L18: =K18-J18 -> -1.68 | Q18: =F18-H18 -> -4.07 | R18: =G18-H18 -> -4.345
C19: LAR NON GADAI | D19: 110 | E19: =INPUT!D108 -> 2 | F19: =INPUT!F108 -> 61.93 | G19: =F19-(F19*10%) -> 55.737 | H19: =INPUT!G108 -> 47.95 | I19: =INPUT!J108 -> 110 | J19: =INPUT!R17 -> 2.2 | K19: =INPUT!K108 -> 2.2 | L19: =K19-J19 -> 0 | Q19: =F19-H19 -> 13.98 | R19: =G19-H19 -> 7.787
C20: LAR EMAS | D20: 110 | E20: =INPUT!D109 -> 2.5 | F20: =INPUT!F109 -> 11.04 | G20: =F20-(F20*10%) -> 9.936 | H20: =INPUT!G109 -> 11.74 | I20: =INPUT!J109 -> 94.08 | J20: =INPUT!R18 -> 2.75 | K20: =INPUT!K109 -> 2.35 | L20: =K20-J20 -> -0.4 | Q20: =F20-H20 -> -0.7 | R20: =G20-H20 -> -1.804
A21: 6 | B21: REVAMP PEGADAIAN BRAND | C21: BRAND AWARENESS | D21: 110 | F21: =INPUT!F110 -> 0 | H21: =INPUT!G110 -> 0 | I21: =INPUT!J110 -> 0 | J21: =INPUT!R19 -> 0 | K21: =INPUT!K110 -> 0 | L21: =K21-J21 -> 0 | Q21: =H21-F21 -> 0 | R21: =H21-G21 -> 0
A22: 7 | B22: GOLD ECOSYSTEM | C22: DEPOSITO EMAS | D22: Unlimited | E22: =INPUT!D111 -> 2.5 | F22: =INPUT!F111 -> 451 | G22: =F22*110% -> 496.1 | H22: =INPUT!G111 -> 242 | I22: =INPUT!J111 -> 53.69 | J22: =INPUT!R20 -> 1.38 | K22: =INPUT!K111 -> 1.34 | L22: =K22-J22 -> -0.04 | Q22: =H22-F22 -> -209 | R22: =H22-G22 -> -254.1
C23: TABUNGAN EMAS | D23: 110 | E23: =INPUT!D112 -> 2.5 | F23: =INPUT!F112 -> 2033 | G23: =F23*110% -> 2236.3 | H23: =INPUT!G112 -> 1498.2072 | I23: =INPUT!J112 -> 73.69 | J23: =INPUT!R21 -> 1.84 | K23: =INPUT!K112 -> 1.84 | L23: =K23-J23 -> 0 | Q23: =H23-F23 -> -534.7928 | R23: =H23-G23 -> -738.0928
C24: GRAMASI PRODUK GALERI 24 | D24: 110 | E24: =INPUT!D113 -> 5 | F24: =INPUT!F113 -> 1356 | G24: =F24*110% -> 1491.6 | H24: =INPUT!G113 -> 474 | I24: =INPUT!J113 -> 34.97 | J24: =INPUT!R22 -> 1.18 | K24: =INPUT!K113 -> 1.75 | L24: =K24-J24 -> 0.57 | Q24: =H24-F24 -> -882 | R24: =H24-G24 -> -1017.6
A25: 8 | B25: PEGADAIAN DIGITAL TRING! | C25: NASABAH TRING! | D25: 110 | E25: =INPUT!D114 -> 5 | F25: =INPUT!F114 -> 988 | G25: =F25*110% -> 1086.8 | H25: =INPUT!G114 -> 756 | I25: =INPUT!J114 -> 76.5 | J25: =INPUT!R23 -> 3.65 | K25: =INPUT!K114 -> 3.82 | L25: =K25-J25 -> 0.17 | Q25: =H25-F25 -> -232 | R25: =H25-G25 -> -330.8
C26: OSL LAYANAN TRING! | D26: 110 | E26: =INPUT!D115 -> 5 | F26: =INPUT!F115 -> 773770278 | G26: =F26*110% -> 8.5114731e+08 | H26: =INPUT!G115 -> 440086127 | I26: =INPUT!J115 -> 56.88 | J26: =INPUT!R24 -> 2.7 | K26: =INPUT!K115 -> 2.84 | L26: =K26-J26 -> 0.14 | Q26: =H26-F26 -> -333684151 | R26: =H26-G26 -> -4.1106118e+08
C27: FREKUENSI TRANSAKSI TRING! | D27: 110 | E27: =INPUT!D116 -> 5 | F27: =INPUT!F116 -> 15493 | G27: =F27*110% -> 17042.3 | H27: =INPUT!G116 -> 4268 | I27: =INPUT!J116 -> 27.55 | J27: =INPUT!R25 -> 1.26 | K27: =INPUT!K116 -> 1.38 | L27: =K27-J27 -> 0.12 | Q27: =H27-F27 -> -11225 | R27: =H27-G27 -> -12774.3
A28: 9 | B28: SINERGI HOLDING UMI | C28: CASHLESS DISBURSEMENT | D28: 110 | E28: =INPUT!D117 -> 2 | F28: =INPUT!F117 -> 78.76 | G28: =F28*110% -> 86.636 | H28: =INPUT!G117 -> 73.43 | I28: =INPUT!J117 -> 93.23 | J28: =INPUT!R26 -> 1.89 | K28: =INPUT!K117 -> 1.86 | L28: =K28-J28 -> -0.03 | Q28: =H28-F28 -> -5.33 | R28: =H28-G28 -> -13.206
C29: OSL SINERGI HOLDING | D29: 110 | E29: =INPUT!D118 -> 1.5 | F29: =INPUT!F118 -> 89612005 | G29: =F29*110% -> 98573206 | H29: =INPUT!G118 -> 355162014 | I29: =INPUT!J118 -> 110 | J29: =INPUT!R27 -> 1.65 | K29: =INPUT!K118 -> 1.65 | L29: =K29-J29 -> 0 | Q29: =H29-F29 -> 265550009 | R29: =H29-G29 -> 2.5658881e+08
C30: TE SINERGI HOLDING | D30: 110 | E30: =INPUT!D119 -> 1.5 | F30: =INPUT!F119 -> 267 | G30: =F30*110% -> 293.7 | H30: =INPUT!G119 -> 55.4114 | I30: =INPUT!J119 -> 20.77 | J30: =INPUT!R28 -> 0.31 | K30: =INPUT!K119 -> 0.31 | L30: =K30-J30 -> 0 | Q30: =H30-F30 -> -211.5886 | R30: =H30-G30 -> -238.2886
A31: 10 | B31: KPI STRETCH GOAL | C31: KPI STRETCH GOAL | F31: =INPUT!F120 -> 1683564317 | G31: =F31*110% -> 1.8519207e+09 | H31: =INPUT!G120 -> 1515917011 | I31: =INPUT!J120 -> 90.04 | J31: =INPUT!R29 -> 0 | K31: =INPUT!K120 -> 0 | L31: =K31-J31 -> 0
A32: TOTAL | E32: =SUM(E5:E31) -> 100 | J32: =SUM(J5:J31) -> 76.89 | K32: =SUM(K5:K31) -> 77.36 | L32: =SUM(L5:L31) -> 0.47

Sheet KALISAT 
A1: 14204 - UPC KALISAT
A2: =KONSOL!A2 -> 46178
A3: NO | B3: KOMPONEN KPI | C3: SUB KOMPONEN KPI | D3: CAPPING | E3: BOBOT KPI | F3: TARGET | H3: REALISASI | I3: ACH (%) | J3: KPI TAHUNAN | L3: DELTA HARIAN | N3: KPI INDIVIDU | Q3: SELISIH TARGET
F4: RKAP | G4: EXCEED | J4: KEMARIN | K4: HARI INI | N4: INDEX | O4: KPI | Q4: RKAP | R4: EXCEED
A5: 1 | B5: OUTSTANDING LOAN | C5: OSL AKTIF RATA-RATA GADAI | D5: Unlimited | E5: =INPUT!D124 -> 10 | F5: =INPUT!F124 -> 25020277303 | G5: =F5*110% -> 2.7522305e+10 | H5: =INPUT!G124 -> 28829140086 | I5: =INPUT!J124 -> 115.22 | J5: =INPUT!S3 -> 11.45 | K5: =INPUT!K124 -> 11.52 | L5: =K5-J5 -> 0.07 | Q5: =H5-F5 -> 3808862783 | R5: =H5-G5 -> 1.3068351e+09
C6: OSL AKTIF RATA-RATA NON GADAI | D6: 110 | E6: =INPUT!D125 -> 5 | F6: =INPUT!F125 -> 6338790652 | G6: =F6*110% -> 6.9726697e+09 | H6: =INPUT!G125 -> 5357216661 | I6: =INPUT!J125 -> 84.51 | J6: =INPUT!S4 -> 4.23 | K6: =INPUT!K125 -> 4.23 | L6: =K6-J6 -> 0 | Q6: =H6-F6 -> -981573991 | R6: =H6-G6 -> -1.6154531e+09
C7: OSL AKTIF RATA-RATA EMAS | D7: Unlimited | E7: =INPUT!D126 -> 7.5 | F7: =INPUT!F126 -> 2269886397 | G7: =F7*110% -> 2.496875e+09 | H7: =INPUT!G126 -> 2135214880 | I7: =INPUT!J126 -> 94.07 | J7: =INPUT!S5 -> 7.1 | K7: =INPUT!K126 -> 7.06 | L7: =K7-J7 -> -0.04 | Q7: =H7-F7 -> -134671517 | R7: =H7-G7 -> -3.6166016e+08
C8: OSL GROSS POSISI | D8: 110 | E8: =INPUT!D127 -> 5 | F8: =INPUT!F127 -> 35200641591 | G8: =F8*110% -> 3.8720706e+10 | H8: =INPUT!G127 -> 37905187824 | I8: =INPUT!J127 -> 107.68 | J8: =INPUT!S6 -> 5.49 | K8: =INPUT!K127 -> 5.38 | L8: =K8-J8 -> -0.11 | Q8: =H8-F8 -> 2704546233 | R8: =H8-G8 -> -8.1551793e+08
A9: 2 | B9: LABA USAHA | C9: LABA USAHA | D9: 110 | E9: =INPUT!D128 -> 10 | F9: =INPUT!F128 -> 5122308848 | G9: =F9*110% -> 5.6345397e+09 | H9: =INPUT!G128 -> 2.415132e+09 | I9: =INPUT!J128 -> 47.15 | J9: =INPUT!S7 -> 4.71 | K9: =INPUT!K128 -> 4.71 | L9: =K9-J9 -> 0 | Q9: =H9-F9 -> -2.7071768e+09 | R9: =H9-G9 -> -3.2194077e+09
A10: 3 | B10: CIR | C10: CIR | D10: 110 | F10: =INPUT!F129 -> 0 | G10: =F10*110% -> 0 | I10: =INPUT!J129 -> 0 | J10: =INPUT!S8 -> 0 | K10: =INPUT!K129 -> 0 | L10: =K10-J10 -> 0 | Q10: =H10-F10 -> 0 | R10: =H10-G10 -> 0
A11: 4 | B11: NASABAH | C11: NASABAH BARU | D11: 110 | E11: =INPUT!D130 -> 5 | F11: =INPUT!F130 -> 1889 | G11: =F11*110% -> 2077.9 | H11: =INPUT!G130 -> 556 | I11: =INPUT!J130 -> 29.44 | J11: =INPUT!S9 -> 1.4 | K11: =INPUT!K130 -> 1.47 | L11: =K11-J11 -> 0.07 | Q11: =H11-F11 -> -1333 | R11: =H11-G11 -> -1521.9
C12: NASABAH BARU AGEN | D12: 110 | E12: =INPUT!D131 -> 2.5 | F12: =INPUT!F131 -> 41 | G12: =F12*110% -> 45.1 | H12: =INPUT!G131 -> 51 | I12: =INPUT!J131 -> 110 | J12: =INPUT!S10 -> 2.75 | K12: =INPUT!K131 -> 2.75 | L12: =K12-J12 -> 0 | Q12: =H12-F12 -> 10 | R12: =H12-G12 -> 5.9
C13: NASABAH PEMBIAYAAN TAHUNAN | D13: 110 | E13: =INPUT!D132 -> 5 | F13: =INPUT!F132 -> 6428 | G13: =F13*110% -> 7070.8 | H13: =INPUT!G132 -> 4450 | I13: =INPUT!J132 -> 69.22 | J13: =INPUT!S11 -> 3.38 | K13: =INPUT!K132 -> 3.46 | L13: =K13-J13 -> 0.08 | Q13: =H13-F13 -> -1978 | R13: =H13-G13 -> -2620.8
C14: NASABAH TABUNGAN EMAS | D14: 110 | E14: =INPUT!D133 -> 5 | F14: =INPUT!F133 -> 284 | G14: =F14*110% -> 312.4 | H14: =INPUT!G133 -> 271 | I14: =INPUT!J133 -> 95.49 | J14: =INPUT!S12 -> 4.79 | K14: =INPUT!K133 -> 4.77 | L14: =K14-J14 -> -0.02 | Q14: =H14-F14 -> -13 | R14: =H14-G14 -> -41.4
A15: 5 | B15: KUALITAS KREDIT | C15: NPL GADAI | D15: 110 | E15: =INPUT!D134 -> 3 | F15: =INPUT!F134 -> 0.31 | G15: =F15-(F15*10%) -> 0.279 | H15: =INPUT!G134 -> 0 | I15: =INPUT!J134 -> 110 | J15: =INPUT!S13 -> 3.3 | K15: =INPUT!K134 -> 3.3 | L15: =K15-J15 -> 0 | Q15: =F15-H15 -> 0.31 | R15: =G15-H15 -> 0.279
C16: NPL NON GADAI | D16: 110 | E16: =INPUT!D135 -> 2 | F16: =INPUT!F135 -> 3.63 | G16: =F16-(F16*10%) -> 3.267 | H16: =INPUT!G135 -> 2.08 | I16: =INPUT!J135 -> 110 | J16: =INPUT!S14 -> 1.11 | K16: =INPUT!K135 -> 2.2 | L16: =K16-J16 -> 1.09 | Q16: =F16-H16 -> 1.55 | R16: =G16-H16 -> 1.187
C17: NPL EMAS | D17: 110 | E17: =INPUT!D136 -> 2.5 | F17: =INPUT!F136 -> 0.87 | G17: =F17-(F17*10%) -> 0.783 | H17: =INPUT!G136 -> 0.71 | I17: =INPUT!J136 -> 110 | J17: =INPUT!S15 -> 2.75 | K17: =INPUT!K136 -> 2.75 | L17: =K17-J17 -> 0 | Q17: =F17-H17 -> 0.16 | R17: =G17-H17 -> 0.073
C18: LAR GADAI | D18: 110 | E18: =INPUT!D137 -> 3 | F18: =INPUT!F137 -> 2.75 | G18: =F18-(F18*10%) -> 2.475 | H18: =INPUT!G137 -> 3.41 | I18: =INPUT!J137 -> 80.77 | J18: =INPUT!S16 -> 2.84 | K18: =INPUT!K137 -> 2.42 | L18: =K18-J18 -> -0.42 | Q18: =F18-H18 -> -0.66 | R18: =G18-H18 -> -0.935
C19: LAR NON GADAI | D19: 110 | E19: =INPUT!D138 -> 2 | F19: =INPUT!F138 -> 14.83 | G19: =F19-(F19*10%) -> 13.347 | H19: =INPUT!G138 -> 16.05 | I19: =INPUT!J138 -> 92.43 | J19: =INPUT!S17 -> 1.11 | K19: =INPUT!K138 -> 1.85 | L19: =K19-J19 -> 0.74 | Q19: =F19-H19 -> -1.22 | R19: =G19-H19 -> -2.703
C20: LAR EMAS | D20: 110 | E20: =INPUT!D139 -> 2.5 | F20: =INPUT!F139 -> 11.04 | G20: =F20-(F20*10%) -> 9.936 | H20: =INPUT!G139 -> 12.3 | I20: =INPUT!J139 -> 89.79 | J20: =INPUT!S18 -> 1.56 | K20: =INPUT!K139 -> 2.24 | L20: =K20-J20 -> 0.68 | Q20: =F20-H20 -> -1.26 | R20: =G20-H20 -> -2.364
A21: 6 | B21: REVAMP PEGADAIAN BRAND | C21: BRAND AWARENESS | D21: 110 | F21: =INPUT!F140 -> 0 | H21: =INPUT!G140 -> 0 | I21: =INPUT!J140 -> 0 | J21: =INPUT!S19 -> 0 | K21: =INPUT!K140 -> 0 | L21: =K21-J21 -> 0 | Q21: =H21-F21 -> 0 | R21: =H21-G21 -> 0
A22: 7 | B22: GOLD ECOSYSTEM | C22: DEPOSITO EMAS | D22: Unlimited | E22: =INPUT!D141 -> 2.5 | F22: =INPUT!F141 -> 563 | G22: =F22*110% -> 619.3 | H22: =INPUT!G141 -> 102 | I22: =INPUT!J141 -> 18.12 | J22: =INPUT!S20 -> 0.45 | K22: =INPUT!K141 -> 0.45 | L22: =K22-J22 -> 0 | Q22: =H22-F22 -> -461 | R22: =H22-G22 -> -517.3
C23: TABUNGAN EMAS | D23: 110 | E23: =INPUT!D142 -> 2.5 | F23: =INPUT!F142 -> 2685 | G23: =F23*110% -> 2953.5 | H23: =INPUT!G142 -> 1882.9887 | I23: =INPUT!J142 -> 70.12 | J23: =INPUT!S21 -> 1.73 | K23: =INPUT!K142 -> 1.75 | L23: =K23-J23 -> 0.02 | Q23: =H23-F23 -> -802.0113 | R23: =H23-G23 -> -1070.5113
C24: GRAMASI PRODUK GALERI 24 | D24: 110 | E24: =INPUT!D143 -> 5 | F24: =INPUT!F143 -> 1521 | G24: =F24*110% -> 1673.1 | H24: =INPUT!G143 -> 597 | I24: =INPUT!J143 -> 39.24 | J24: =INPUT!S22 -> 1.95 | K24: =INPUT!K143 -> 1.96 | L24: =K24-J24 -> 0.01 | Q24: =H24-F24 -> -924 | R24: =H24-G24 -> -1076.1
A25: 8 | B25: PEGADAIAN DIGITAL TRING! | C25: NASABAH TRING! | D25: 110 | E25: =INPUT!D144 -> 5 | F25: =INPUT!F144 -> 1067 | G25: =F25*110% -> 1173.7 | H25: =INPUT!G144 -> 936 | I25: =INPUT!J144 -> 87.73 | J25: =INPUT!S23 -> 4.28 | K25: =INPUT!K144 -> 4.39 | L25: =K25-J25 -> 0.11 | Q25: =H25-F25 -> -131 | R25: =H25-G25 -> -237.7
C26: OSL LAYANAN TRING! | D26: 110 | E26: =INPUT!D145 -> 5 | F26: =INPUT!F145 -> 773770278 | G26: =F26*110% -> 8.5114731e+08 | H26: =INPUT!G145 -> 499550711 | I26: =INPUT!J145 -> 64.56 | J26: =INPUT!S24 -> 3.36 | K26: =INPUT!K145 -> 3.23 | L26: =K26-J26 -> -0.13 | Q26: =H26-F26 -> -274219567 | R26: =H26-G26 -> -3.5159659e+08
C27: FREKUENSI TRANSAKSI TRING! | D27: 110 | E27: =INPUT!D146 -> 5 | F27: =INPUT!F146 -> 10259 | G27: =F27*110% -> 11284.9 | H27: =INPUT!G146 -> 3792 | I27: =INPUT!J146 -> 36.96 | J27: =INPUT!S25 -> 1.75 | K27: =INPUT!K146 -> 1.85 | L27: =K27-J27 -> 0.1 | Q27: =H27-F27 -> -6467 | R27: =H27-G27 -> -7492.9
A28: 9 | B28: SINERGI HOLDING UMI | C28: CASHLESS DISBURSEMENT | D28: 110 | E28: =INPUT!D147 -> 2 | F28: =INPUT!F147 -> 78.76 | G28: =F28*110% -> 86.636 | H28: =INPUT!G147 -> 84.48 | I28: =INPUT!J147 -> 107.26 | J28: =INPUT!S26 -> 2.14 | K28: =INPUT!K147 -> 2.15 | L28: =K28-J28 -> 0.01 | Q28: =H28-F28 -> 5.72 | R28: =H28-G28 -> -2.156
C29: OSL SINERGI HOLDING | D29: 110 | E29: =INPUT!D148 -> 1.5 | F29: =INPUT!F148 -> 89612005 | G29: =F29*110% -> 98573206 | H29: =INPUT!G148 -> 232396800 | I29: =INPUT!J148 -> 110 | J29: =INPUT!S27 -> 1.65 | K29: =INPUT!K148 -> 1.65 | L29: =K29-J29 -> 0 | Q29: =H29-F29 -> 142784795 | R29: =H29-G29 -> 1.3382359e+08
C30: TE SINERGI HOLDING | D30: 110 | E30: =INPUT!D149 -> 1.5 | F30: =INPUT!F149 -> 321 | G30: =F30*110% -> 353.1 | H30: =INPUT!G149 -> 278.4685 | I30: =INPUT!J149 -> 86.65 | J30: =INPUT!S28 -> 1.29 | K30: =INPUT!K149 -> 1.3 | L30: =K30-J30 -> 0.01 | Q30: =H30-F30 -> -42.5315 | R30: =H30-G30 -> -74.6315
A31: 10 | B31: KPI STRETCH GOAL | C31: KPI STRETCH GOAL | F31: =INPUT!F150 -> 2154951957 | H31: =INPUT!G150 -> 1466083882 | I31: =INPUT!J150 -> 68.03 | J31: =INPUT!S29 -> 0 | K31: =INPUT!K150 -> 0 | L31: =K31-J31 -> 0
A32: TOTAL | E32: =SUM(E5:E31) -> 100 | J32: =SUM(J5:J31) -> 76.57 | K32: =SUM(K5:K31) -> 78.84 | L32: =SUM(L5:L31) -> 2.27

Sheet MAYANG
A1: 14205 - UPC MAYANG
A2: =KONSOL!A2 -> 46178
A3: NO | B3: KOMPONEN KPI | C3: SUB KOMPONEN KPI | D3: CAPPING | E3: BOBOT KPI | F3: TARGET | H3: REALISASI | I3: ACH (%) | J3: KPI TAHUNAN | L3: DELTA HARIAN | N3: KPI INDIVIDU | Q3: SELISIH TARGET
F4: RKAP | G4: EXCEED | J4: KEMARIN | K4: HARI INI | N4: INDEX | O4: KPI | Q4: RKAP | R4: EXCEED
A5: 1 | B5: OUTSTANDING LOAN | C5: OSL AKTIF RATA-RATA GADAI | D5: Unlimited | E5: =INPUT!D154 -> 12.5 | F5: =INPUT!F154 -> 8226946715 | G5: =F5*110% -> 9.0496414e+09 | H5: =INPUT!G154 -> 10702857731 | I5: =INPUT!J154 -> 130.1 | J5: =INPUT!T3 -> 16.18 | K5: =INPUT!K154 -> 16.26 | L5: =K5-J5 -> 0.08 | Q5: =H5-F5 -> 2475911016 | R5: =H5-G5 -> 1.6532163e+09
C6: OSL AKTIF RATA-RATA NON GADAI | D6: 110 | F6: =INPUT!F155 -> 348962534 | G6: =F6*110% -> 3.8385879e+08 | H6: =INPUT!G155 -> 498264482 | I6: =INPUT!J155 -> 0 | J6: =INPUT!T4 -> 0 | K6: =INPUT!K155 -> 0 | L6: =K6-J6 -> 0 | Q6: =H6-F6 -> 149301948 | R6: =H6-G6 -> 1.1440569e+08
C7: OSL AKTIF RATA-RATA EMAS | D7: Unlimited | E7: =INPUT!D156 -> 10 | F7: =INPUT!F156 -> 2123756680 | G7: =F7*110% -> 2336132348 | H7: =INPUT!G156 -> 1283628662 | I7: =INPUT!J156 -> 60.44 | J7: =INPUT!T5 -> 6 | K7: =INPUT!K156 -> 6.04 | L7: =K7-J7 -> 0.04 | Q7: =H7-F7 -> -840128018 | R7: =H7-G7 -> -1052503686
C8: OSL GROSS POSISI | D8: 110 | E8: =INPUT!D157 -> 5 | F8: =INPUT!F157 -> 10848655273 | G8: =F8*110% -> 1.1933521e+10 | H8: =INPUT!G157 -> 13220402907 | I8: =INPUT!J157 -> 110 | J8: =INPUT!T6 -> 5.5 | K8: =INPUT!K157 -> 5.5 | L8: =K8-J8 -> 0 | Q8: =H8-F8 -> 2371747634 | R8: =H8-G8 -> 1.2868821e+09
A9: 2 | B9: LABA USAHA | C9: LABA USAHA | D9: 110 | E9: =INPUT!D158 -> 10 | F9: =INPUT!F158 -> 1660074089 | G9: =F9*110% -> 1.8260815e+09 | H9: =INPUT!G158 -> 7.2163532e+08 | I9: =INPUT!J158 -> 43.47 | J9: =INPUT!T7 -> 4.35 | K9: =INPUT!K158 -> 4.35 | L9: =K9-J9 -> 0 | Q9: =H9-F9 -> -9.3843877e+08 | R9: =H9-G9 -> -1.1044462e+09
A10: 3 | B10: CIR | C10: CIR | D10: 110 | F10: =INPUT!F159 -> 0 | G10: =F10*110% -> 0 | H10: =INPUT!G159 -> 24.96 | I10: =INPUT!J159 -> 0 | J10: =INPUT!T8 -> 0 | K10: =INPUT!K159 -> 0 | L10: =K10-J10 -> 0 | Q10: =H10-F10 -> 24.96 | R10: =H10-G10 -> 24.96
A11: 4 | B11: NASABAH | C11: NASABAH BARU | D11: 110 | E11: =INPUT!D160 -> 5 | F11: =INPUT!F160 -> 1197 | G11: =F11*110% -> 1316.7 | H11: =INPUT!G160 -> 339 | I11: =INPUT!J160 -> 28.31 | J11: =INPUT!T9 -> 0.94 | K11: =INPUT!K160 -> 1.42 | L11: =K11-J11 -> 0.48 | Q11: =H11-F11 -> -858 | R11: =H11-G11 -> -977.7
C12: NASABAH BARU AGEN | D12: 110 | E12: =INPUT!D161 -> 2.5 | F12: =INPUT!F161 -> 108 | G12: =F12*110% -> 118.8 | H12: =INPUT!G161 -> 58 | I12: =INPUT!J161 -> 53.56 | J12: =INPUT!T10 -> 1.29 | K12: =INPUT!K161 -> 1.34 | L12: =K12-J12 -> 0.05 | Q12: =H12-F12 -> -50 | R12: =H12-G12 -> -60.8
C13: NASABAH PEMBIAYAAN TAHUNAN | D13: 110 | E13: =INPUT!D162 -> 5 | F13: =INPUT!F162 -> 3048 | G13: =F13*110% -> 3352.8 | H13: =INPUT!G162 -> 1985 | I13: =INPUT!J162 -> 65.12 | J13: =INPUT!T11 -> 3 | K13: =INPUT!K162 -> 3.26 | L13: =K13-J13 -> 0.26 | Q13: =H13-F13 -> -1063 | R13: =H13-G13 -> -1367.8
C14: NASABAH TABUNGAN EMAS | D14: 110 | E14: =INPUT!D163 -> 5 | F14: =INPUT!F163 -> 136 | G14: =F14*110% -> 149.6 | H14: =INPUT!G163 -> 124 | I14: =INPUT!J163 -> 91.03 | J14: =INPUT!T12 -> 4.59 | K14: =INPUT!K163 -> 4.55 | L14: =K14-J14 -> -0.04 | Q14: =H14-F14 -> -12 | R14: =H14-G14 -> -25.6
A15: 5 | B15: KUALITAS KREDIT | C15: NPL GADAI | D15: 110 | E15: =INPUT!D164 -> 3 | F15: =INPUT!F164 -> 0.31 | G15: =F15-(F15*10%) -> 0.279 | H15: =INPUT!G164 -> 0 | I15: =INPUT!J164 -> 110 | J15: =INPUT!T13 -> 3.3 | K15: =INPUT!K164 -> 3.3 | L15: =K15-J15 -> 0 | Q15: =F15-H15 -> 0.31 | R15: =G15-H15 -> 0.279
C16: NPL NON GADAI | D16: 110 | E16: =INPUT!D165 -> 2 | F16: =INPUT!F165 -> 14.97 | G16: =F16-(F16*10%) -> 13.473 | H16: =INPUT!G165 -> 5.54 | I16: =INPUT!J165 -> 110 | J16: =INPUT!T14 -> 2.2 | K16: =INPUT!K165 -> 2.2 | L16: =K16-J16 -> 0 | Q16: =F16-H16 -> 9.43 | R16: =G16-H16 -> 7.933
C17: NPL EMAS | D17: 110 | E17: =INPUT!D166 -> 2.5 | F17: =INPUT!F166 -> 0.87 | G17: =F17-(F17*10%) -> 0.783 | H17: =INPUT!G166 -> 0 | I17: =INPUT!J166 -> 110 | J17: =INPUT!T15 -> 2.75 | K17: =INPUT!K166 -> 2.75 | L17: =K17-J17 -> 0 | Q17: =F17-H17 -> 0.87 | R17: =G17-H17 -> 0.783
C18: LAR GADAI | D18: 110 | E18: =INPUT!D167 -> 3 | F18: =INPUT!F167 -> 2.75 | G18: =F18-(F18*10%) -> 2.475 | H18: =INPUT!G167 -> 5.62 | I18: =INPUT!J167 -> 49.01 | J18: =INPUT!T16 -> 3.3 | K18: =INPUT!K167 -> 1.47 | L18: =K18-J18 -> -1.83 | Q18: =F18-H18 -> -2.87 | R18: =G18-H18 -> -3.145
C19: LAR NON GADAI | D19: 110 | E19: =INPUT!D168 -> 2 | F19: =INPUT!F168 -> 23.86 | G19: =F19-(F19*10%) -> 21.474 | H19: =INPUT!G168 -> 30.5 | I19: =INPUT!J168 -> 78.24 | J19: =INPUT!T17 -> 0.73 | K19: =INPUT!K168 -> 1.56 | L19: =K19-J19 -> 0.83 | Q19: =F19-H19 -> -6.64 | R19: =G19-H19 -> -9.026
C20: LAR EMAS | D20: 110 | E20: =INPUT!D169 -> 2.5 | F20: =INPUT!F169 -> 11.04 | G20: =F20-(F20*10%) -> 9.936 | H20: =INPUT!G169 -> 8.61 | I20: =INPUT!J169 -> 110 | J20: =INPUT!T18 -> 2.75 | K20: =INPUT!K169 -> 2.75 | L20: =K20-J20 -> 0 | Q20: =F20-H20 -> 2.43 | R20: =G20-H20 -> 1.326
A21: 6 | B21: REVAMP PEGADAIAN BRAND | C21: BRAND AWARENESS | D21: 110 | F21: =INPUT!F170 -> 0 | H21: =INPUT!G170 -> 0 | I21: =INPUT!J170 -> 0 | J21: =INPUT!T19 -> 0 | K21: =INPUT!K170 -> 0 | L21: =K21-J21 -> 0 | Q21: =H21-F21 -> 0 | R21: =H21-G21 -> 0
A22: 7 | B22: GOLD ECOSYSTEM | C22: DEPOSITO EMAS | D22: Unlimited | E22: =INPUT!D171 -> 2.5 | F22: =INPUT!F171 -> 321 | G22: =F22*110% -> 353.1 | H22: =INPUT!G171 -> 129 | I22: =INPUT!J171 -> 40.13 | J22: =INPUT!T20 -> 1.12 | K22: =INPUT!K171 -> 1 | L22: =K22-J22 -> -0.12 | Q22: =H22-F22 -> -192 | R22: =H22-G22 -> -224.1
C23: TABUNGAN EMAS | D23: 110 | E23: =INPUT!D172 -> 2.5 | F23: =INPUT!F172 -> 1505 | G23: =F23*110% -> 1655.5 | H23: =INPUT!G172 -> 875.4505 | I23: =INPUT!J172 -> 58.18 | J23: =INPUT!T21 -> 1.47 | K23: =INPUT!K172 -> 1.45 | L23: =K23-J23 -> -0.02 | Q23: =H23-F23 -> -629.5495 | R23: =H23-G23 -> -780.0495
C24: GRAMASI PRODUK GALERI 24 | D24: 110 | E24: =INPUT!D173 -> 5 | F24: =INPUT!F173 -> 129 | G24: =F24*110% -> 141.9 | H24: =INPUT!G173 -> 410.5 | I24: =INPUT!J173 -> 31.81 | J24: =INPUT!T22 -> 1.48 | K24: =INPUT!K173 -> 1.59 | L24: =K24-J24 -> 0.11 | Q24: =H24-F24 -> 281.5 | R24: =H24-G24 -> 268.6
A25: 8 | B25: PEGADAIAN DIGITAL TRING! | C25: NASABAH TRING! | D25: 110 | E25: =INPUT!D174 -> 5 | F25: =INPUT!F174 -> 902 | G25: =F25*110% -> 992.2 | H25: =INPUT!G174 -> 377 | I25: =INPUT!J174 -> 41.82 | J25: =INPUT!T23 -> 2.02 | K25: =INPUT!K174 -> 2.09 | L25: =K25-J25 -> 0.07 | Q25: =H25-F25 -> -525 | R25: =H25-G25 -> -615.2
C26: OSL LAYANAN TRING! | D26: 110 | E26: =INPUT!D175 -> 5 | F26: =INPUT!F175 -> 773770278 | G26: =F26*110% -> 8.5114731e+08 | H26: =INPUT!G175 -> 248578403 | I26: =INPUT!J175 -> 32.13 | J26: =INPUT!T24 -> 1.6 | K26: =INPUT!K175 -> 1.61 | L26: =K26-J26 -> 0.01 | Q26: =H26-F26 -> -525191875 | R26: =H26-G26 -> -6.025689e+08
C27: FREKUENSI TRANSAKSI TRING! | D27: 110 | E27: =INPUT!D176 -> 5 | F27: =INPUT!F176 -> 8126 | G27: =F27*110% -> 8938.6 | H27: =INPUT!G176 -> 1630 | I27: =INPUT!J176 -> 20.06 | J27: =INPUT!T25 -> 0.92 | K27: =INPUT!K176 -> 1 | L27: =K27-J27 -> 0.08 | Q27: =H27-F27 -> -6496 | R27: =H27-G27 -> -7308.6
A28: 9 | B28: SINERGI HOLDING UMI | C28: CASHLESS DISBURSEMENT | D28: 110 | E28: =INPUT!D177 -> 2 | F28: =INPUT!F177 -> 78.76 | G28: =F28*110% -> 86.636 | H28: =INPUT!G177 -> 89.09 | I28: =INPUT!J177 -> 110 | J28: =INPUT!T26 -> 2.2 | K28: =INPUT!K177 -> 2.2 | L28: =K28-J28 -> 0 | Q28: =H28-F28 -> 10.33 | R28: =H28-G28 -> 2.454
C29: OSL SINERGI HOLDING | D29: 110 | E29: =INPUT!D178 -> 1.5 | F29: =INPUT!F178 -> 89612005 | G29: =F29*110% -> 98573206 | H29: =INPUT!G178 -> 232844750 | I29: =INPUT!J178 -> 110 | J29: =INPUT!T27 -> 1.65 | K29: =INPUT!K178 -> 1.65 | L29: =K29-J29 -> 0 | Q29: =H29-F29 -> 143232745 | R29: =H29-G29 -> 1.3427154e+08
C30: TE SINERGI HOLDING | D30: 110 | E30: =INPUT!D179 -> 1.5 | F30: =INPUT!F179 -> 216 | G30: =F30*110% -> 237.6 | H30: =INPUT!G179 -> 135.8103 | I30: =INPUT!J179 -> 62.88 | J30: =INPUT!T28 -> 0.9 | K30: =INPUT!K179 -> 0.94 | L30: =K30-J30 -> 0.04 | Q30: =H30-F30 -> -80.1897 | R30: =H30-G30 -> -101.7897
A31: 10 | B31: KPI STRETCH GOAL | C31: KPI STRETCH GOAL | F31: =INPUT!F180 -> 2245564130 | H31: =INPUT!G180 -> 1225719385 | I31: =INPUT!J180 -> 54.58 | J31: =INPUT!T29 -> 0 | K31: =INPUT!K180 -> 0 | L31: =K31-J31 -> 0
A32: TOTAL | E32: =SUM(E5:E31) -> 100 | J32: =SUM(J5:J31) -> 70.24 | K32: =SUM(K5:K31) -> 70.28 | L32: =SUM(L5:L31) -> 0.04

Sheet COLO SUMBERJATI
A1: 17506 - COLO SUMBERJATI
A2: =KONSOL!A2 -> 46178
A3: NO | B3: KOMPONEN KPI | C3: SUB KOMPONEN KPI | D3: CAPPING | E3: BOBOT KPI | F3: TARGET | H3: REALISASI | I3: ACH (%) | J3: KPI TAHUNAN | L3: DELTA HARIAN | N3: KPI INDIVIDU | Q3: SELISIH TARGET
F4: RKAP | G4: EXCEED | J4: KEMARIN | K4: HARI INI | N4: INDEX | O4: KPI | Q4: RKAP | R4: EXCEED
